Workbook

Sheet 결과
A2: 반사율 극값 기반 두께 추정
A3: Nb2O5 단층 두께와 Nb2O5/SiO2 적층의 SiO2 TMM 역산 두께를 13개 위치에서 계산합니다.
A4: Nb2O5 (1L) | B4: 값 | D4: SiO2 TMM 역산 | E4: 값
A5: 평균 (nm) | B5: =IF(COUNT(G12:G24)=0,"",AVERAGE(G12:G24)) -> 104.67341 | D5: 평균 (nm) | E5: =IF(COUNT(N12:N24)=0,"",AVERAGE(N12:N24)) -> 96.210254
A6: 최소 (nm) | B6: =IF(COUNT(G12:G24)=0,"",MIN(G12:G24)) -> 94.377611 | D6: 최소 (nm) | E6: =IF(COUNT(N12:N24)=0,"",MIN(N12:N24)) -> 94.359263
A7: 최대 (nm) | B7: =IF(COUNT(G12:G24)=0,"",MAX(G12:G24)) -> 113.74318 | D7: 최대 (nm) | E7: =IF(COUNT(N12:N24)=0,"",MAX(N12:N24)) -> 99.152109
A8: P-P (nm) | B8: =IF(COUNT(G12:G24)=0,"",MAX(G12:G24)-MIN(G12:G24)) -> 19.36557 | D8: P-P (nm) | E8: =IF(COUNT(N12:N24)=0,"",MAX(N12:N24)-MIN(N12:N24)) -> 4.7928463
A9: ± 균일도 | B9: =IF(COUNT(G12:G24)=0,"",(MAX(G12:G24)-MIN(G12:G24))/(2*AVERAGE(G12:G24))) -> 0.092504727 | D9: ± 균일도 | E9: =IF(COUNT(N12:N24)=0,"",(MAX(N12:N24)-MIN(N12:N24))/(2*AVERAGE(N12:N24))) -> 0.024908189
A11: 시료 | B11: 위치(mm) | C11: Nb 최소 λ | D11: Nb 최대 λ | E11: Nb 사용 λ | F11: Nb n | G11: Nb 두께(nm) | H11: Nb 상태 | I11: 2L 최소 λ | J11: 2L 최대 λ | K11: 2L 사용 λ | L11: SiO2 n | M11: 하부 Nb2O5(nm) | N11: SiO2 TMM 두께(nm) | O11: 2L 상태
A12: ='Nb2O5 입력'!A6 -> 1 | B12: =설정!B16 -> 50 | C12: ='Nb2O5 입력'!AV6 -> 470 | D12: ='Nb2O5 입력'!AX6 -> 600 | E12: ='Nb2O5 입력'!AZ6 -> 470 | F12: ='Nb2O5 입력'!BA6 -> 2.36641 | G12: ='Nb2O5 입력'!BC6 -> 99.306545 | H12: ='Nb2O5 입력'!BD6 -> 완료 | I12: ='2층 입력'!AV6 -> 475 | J12: ='2층 입력'!AX6 -> 550 | K12: ='2층 입력'!AZ6 -> 475 | L12: ='2층 입력'!BA6 -> 1.47085 | M12: ='2층 입력'!BB6 -> 10 | N12: ='2층 입력'!BC6 -> 95.324239 | O12: ='2층 입력'!BD6 -> 완료
A13: ='Nb2O5 입력'!A7 -> 2 | B13: =설정!B17 -> 150 | C13: ='Nb2O5 입력'!AV7 -> 500 | D13: ='Nb2O5 입력'!AX7 -> 430 | E13: ='Nb2O5 입력'!AZ7 -> 500 | F13: ='Nb2O5 입력'!BA7 -> 2.3457 | G13: ='Nb2O5 입력'!BC7 -> 106.57799 | H13: ='Nb2O5 입력'!BD7 -> 완료 | I13: ='2층 입력'!AV7 -> 495 | J13: ='2층 입력'!AX7 -> 430 | K13: ='2층 입력'!AZ7 -> 495 | L13: ='2층 입력'!BA7 -> 1.47025 | M13: ='2층 입력'!BB7 -> 10 | N13: ='2층 입력'!BC7 -> 99.152109 | O13: ='2층 입력'!BD7 -> 완료
A14: ='Nb2O5 입력'!A8 -> 3 | B14: =설정!B18 -> 250 | C14: ='Nb2O5 입력'!AV8 -> 510 | D14: ='Nb2O5 입력'!AX8 -> 430 | E14: ='Nb2O5 입력'!AZ8 -> 510 | F14: ='Nb2O5 입력'!BA8 -> 2.33996 | G14: ='Nb2O5 입력'!BC8 -> 108.97622 | H14: ='Nb2O5 입력'!BD8 -> 완료 | I14: ='2층 입력'!AV8 -> 485 | J14: ='2층 입력'!AX8 -> 430 | K14: ='2층 입력'!AZ8 -> 485 | L14: ='2층 입력'!BA8 -> 1.47054 | M14: ='2층 입력'!BB8 -> 10 | N14: ='2층 입력'!BC8 -> 97.244 | O14: ='2층 입력'!BD8 -> 완료
A15: ='Nb2O5 입력'!A9 -> 4 | B15: =설정!B19 -> 350 | C15: ='Nb2O5 입력'!AV9 -> 520 | D15: ='Nb2O5 입력'!AX9 -> 430 | E15: ='Nb2O5 입력'!AZ9 -> 520 | F15: ='Nb2O5 입력'!BA9 -> 2.33468 | G15: ='Nb2O5 입력'!BC9 -> 111.3643 | H15: ='Nb2O5 입력'!BD9 -> 완료 | I15: ='2층 입력'!AV9 -> 480 | J15: ='2층 입력'!AX9 -> 430 | K15: ='2층 입력'!AZ9 -> 480 | L15: ='2층 입력'!BA9 -> 1.47069 | M15: ='2층 입력'!BB9 -> 10 | N15: ='2층 입력'!BC9 -> 96.286803 | O15: ='2층 입력'!BD9 -> 완료
A16: ='Nb2O5 입력'!A10 -> 5 | B16: =설정!B20 -> 450 | C16: ='Nb2O5 입력'!AV10 -> 530 | D16: ='Nb2O5 입력'!AX10 -> 430 | E16: ='Nb2O5 입력'!AZ10 -> 530 | F16: ='Nb2O5 입력'!BA10 -> 2.32981 | G16: ='Nb2O5 입력'!BC10 -> 113.74318 | H16: ='Nb2O5 입력'!BD10 -> 완료 | I16: ='2층 입력'!AV10 -> 480 | J16: ='2층 입력'!AX10 -> 430 | K16: ='2층 입력'!AZ10 -> 480 | L16: ='2층 입력'!BA10 -> 1.47069 | M16: ='2층 입력'!BB10 -> 10 | N16: ='2층 입력'!BC10 -> 96.286803 | O16: ='2층 입력'!BD10 -> 완료
A17: ='Nb2O5 입력'!A11 -> 6 | B17: =설정!B21 -> 550 | C17: ='Nb2O5 입력'!AV11 -> 520 | D17: ='Nb2O5 입력'!AX11 -> 430 | E17: ='Nb2O5 입력'!AZ11 -> 520 | F17: ='Nb2O5 입력'!BA11 -> 2.33468 | G17: ='Nb2O5 입력'!BC11 -> 111.3643 | H17: ='Nb2O5 입력'!BD11 -> 완료 | I17: ='2층 입력'!AV11 -> 480 | J17: ='2층 입력'!AX11 -> 430 | K17: ='2층 입력'!AZ11 -> 480 | L17: ='2층 입력'!BA11 -> 1.47069 | M17: ='2층 입력'!BB11 -> 10 | N17: ='2층 입력'!BC11 -> 96.286803 | O17: ='2층 입력'!BD11 -> 완료
A18: ='Nb2O5 입력'!A12 -> 7 | B18: =설정!B22 -> 650 | C18: ='Nb2O5 입력'!AV12 -> 520 | D18: ='Nb2O5 입력'!AX12 -> 430 | E18: ='Nb2O5 입력'!AZ12 -> 520 | F18: ='Nb2O5 입력'!BA12 -> 2.33468 | G18: ='Nb2O5 입력'!BC12 -> 111.3643 | H18: ='Nb2O5 입력'!BD12 -> 완료 | I18: ='2층 입력'!AV12 -> 480 | J18: ='2층 입력'!AX12 -> 430 | K18: ='2층 입력'!AZ12 -> 480 | L18: ='2층 입력'!BA12 -> 1.47069 | M18: ='2층 입력'!BB12 -> 10 | N18: ='2층 입력'!BC12 -> 96.286803 | O18: ='2층 입력'!BD12 -> 완료
A19: ='Nb2O5 입력'!A13 -> 8 | B19: =설정!B23 -> 750 | C19: ='Nb2O5 입력'!AV13 -> 510 | D19: ='Nb2O5 입력'!AX13 -> 430 | E19: ='Nb2O5 입력'!AZ13 -> 510 | F19: ='Nb2O5 입력'!BA13 -> 2.33996 | G19: ='Nb2O5 입력'!BC13 -> 108.97622 | H19: ='Nb2O5 입력'!BD13 -> 완료 | I19: ='2층 입력'!AV13 -> 470 | J19: ='2층 입력'!AX13 -> 550 | K19: ='2층 입력'!AZ13 -> 470 | L19: ='2층 입력'!BA13 -> 1.47101 | M19: ='2층 입력'!BB13 -> 10 | N19: ='2층 입력'!BC13 -> 94.359263 | O19: ='2층 입력'!BD13 -> 완료
A20: ='Nb2O5 입력'!A14 -> 9 | B20: =설정!B24 -> 850 | C20: ='Nb2O5 입력'!AV14 -> 490 | D20: ='Nb2O5 입력'!AX14 -> 600 | E20: ='Nb2O5 입력'!AZ14 -> 490 | F20: ='Nb2O5 입력'!BA14 -> 2.35198 | G20: ='Nb2O5 입력'!BC14 -> 104.16755 | H20: ='Nb2O5 입력'!BD14 -> 완료 | I20: ='2층 입력'!AV14 -> 470 | J20: ='2층 입력'!AX14 -> 550 | K20: ='2층 입력'!AZ14 -> 470 | L20: ='2층 입력'!BA14 -> 1.47101 | M20: ='2층 입력'!BB14 -> 10 | N20: ='2층 입력'!BC14 -> 94.359263 | O20: ='2층 입력'!BD14 -> 완료
A21: ='Nb2O5 입력'!A15 -> 10 | B21: =설정!B25 -> 950 | C21: ='Nb2O5 입력'!AV15 -> 470 | D21: ='Nb2O5 입력'!AX15 -> 600 | E21: ='Nb2O5 입력'!AZ15 -> 470 | F21: ='Nb2O5 입력'!BA15 -> 2.36641 | G21: ='Nb2O5 입력'!BC15 -> 99.306545 | H21: ='Nb2O5 입력'!BD15 -> 완료 | I21: ='2층 입력'!AV15 -> 480 | J21: ='2층 입력'!AX15 -> 430 | K21: ='2층 입력'!AZ15 -> 480 | L21: ='2층 입력'!BA15 -> 1.47069 | M21: ='2층 입력'!BB15 -> 10 | N21: ='2층 입력'!BC15 -> 96.286803 | O21: ='2층 입력'!BD15 -> 완료
A22: ='Nb2O5 입력'!A16 -> 11 | B22: =설정!B26 -> 1050 | C22: ='Nb2O5 입력'!AV16 -> 460 | D22: ='Nb2O5 입력'!AX16 -> 600 | E22: ='Nb2O5 입력'!AZ16 -> 460 | F22: ='Nb2O5 입력'!BA16 -> 2.37476 | G22: ='Nb2O5 입력'!BC16 -> 96.851892 | H22: ='Nb2O5 입력'!BD16 -> 완료 | I22: ='2층 입력'!AV16 -> 480 | J22: ='2층 입력'!AX16 -> 430 | K22: ='2층 입력'!AZ16 -> 480 | L22: ='2층 입력'!BA16 -> 1.47069 | M22: ='2층 입력'!BB16 -> 10 | N22: ='2층 입력'!BC16 -> 96.286803 | O22: ='2층 입력'!BD16 -> 완료
A23: ='Nb2O5 입력'!A17 -> 12 | B23: =설정!B27 -> 1150 | C23: ='Nb2O5 입력'!AV17 -> 450 | D23: ='Nb2O5 입력'!AX17 -> 600 | E23: ='Nb2O5 입력'!AZ17 -> 450 | F23: ='Nb2O5 입력'!BA17 -> 2.38404 | G23: ='Nb2O5 입력'!BC17 -> 94.377611 | H23: ='Nb2O5 입력'!BD17 -> 완료 | I23: ='2층 입력'!AV17 -> 480 | J23: ='2층 입력'!AX17 -> 430 | K23: ='2층 입력'!AZ17 -> 480 | L23: ='2층 입력'!BA17 -> 1.47069 | M23: ='2층 입력'!BB17 -> 10 | N23: ='2층 입력'!BC17 -> 96.286803 | O23: ='2층 입력'!BD17 -> 완료
A24: ='Nb2O5 입력'!A18 -> 13 | B24: =설정!B28 -> 1250 | C24: ='Nb2O5 입력'!AV18 -> 450 | D24: ='Nb2O5 입력'!AX18 -> 600 | E24: ='Nb2O5 입력'!AZ18 -> 450 | F24: ='Nb2O5 입력'!BA18 -> 2.38404 | G24: ='Nb2O5 입력'!BC18 -> 94.377611 | H24: ='Nb2O5 입력'!BD18 -> 완료 | I24: ='2층 입력'!AV18 -> 480 | J24: ='2층 입력'!AX18 -> 430 | K24: ='2층 입력'!AZ18 -> 480 | L24: ='2층 입력'!BA18 -> 1.47069 | M24: ='2층 입력'!BB18 -> 10 | N24: ='2층 입력'!BC18 -> 96.286803 | O24: ='2층 입력'!BD18 -> 완료

Sheet 설정
A2: 계산 설정
A3: 노란색 셀을 조정하면 13개 위치의 결과가 즉시 다시 계산됩니다.
A5: 계산 대상 | B5: 광학 모델 | C5: 극값 | D5: 차수 p | E5: 검색 시작(nm) | F5: 검색 끝(nm) | G5: 입사각 θ0(°)
A7: Nb2O5 (1L) | B7: air/Nb2O5/PET · 위상반전 1회 | C7: 최소 | D7: 1 | E7: 430 | F7: 600 | G7: 0
A8: SiO2 (2L) | B8: air/SiO2/Nb2O5/PET · TMM 역산 | C8: 최소 | D8: 1 | E8: 430 | F8: 550 | G8: 0
A10: 계산식
A11: Nb2O5 | B11: 최소 d=pλ/(2ncosθf), 최대 d=(2p-1)λ/(4ncosθf)
A12: SiO2 (2L) | B12: 하부 Nb2O5 두께와 PET를 포함한 TMM 반사율 최소 파장→SiO2 두께 역산(차수 p 미사용)
A13: 굴절각 | B13: θf=asin(sinθ0/n). 기본 θ0=0°이며 필요 시 설정에서 변경
A15: 시료 | B15: 위치(mm) | C15: 하부 Nb2O5(nm) | D15: 사용 방법
A16: 1 | B16: 50 | C16: 10 | D16: 1. 각 입력 시트의 A:AT 노란색 영역에 CM-36dG 13개 행을 붙여넣습니다.
A17: 2 | B17: 150 | C17: 10 | D17: 2. 설정 C16:C28에 2층 시료의 위치별 하부 Nb2O5 두께(8–15 nm)를 입력합니다.
A18: 3 | B18: 250 | C18: 10 | D18: 3. 평탄부·경계값·잘못 선택된 극값은 AY열의 수동 파장으로 보정합니다.
A19: 4 | B19: 350 | C19: 10 | D19: 4. 결과 시트에서 13개 위치의 파장, 굴절률, 두께와 균일도를 확인합니다.
A20: 5 | B20: 450 | C20: 10 | D20: 5. 2층 SiO2는 TMM 계산이며 차수 p와 입사각 설정을 사용하지 않습니다.
A21: 6 | B21: 550 | C21: 10 | D21: 노란색은 입력 셀입니다. 수식 셀은 직접 덮어쓰지 마세요.
A22: 7 | B22: 650 | C22: 10
A23: 8 | B23: 750 | C23: 10
A24: 9 | B24: 850 | C24: 10
A25: 10 | B25: 950 | C25: 10
A26: 11 | B26: 1050 | C26: 10
A27: 12 | B27: 1150 | C27: 10
A28: 13 | B28: 1250 | C28: 10
A32: 가정 및 한계
A33: 단층식 | B33: 첨부 굴절률의 실수부 n만 사용한 광학 두께 기반 추정입니다.
A34: 2층 TMM | B34: Air/SiO2/Nb2O5/PET 구조의 정상입사 TMM으로 계산한 최저 반사율 파장과 측정 파장이 일치하는 SiO2 두께를 역산합니다.
A35: 간섭 차수 | B35: 한 개 극값만으로 차수 p를 고유하게 정할 수 없습니다. 알려진 목표 두께 또는 공정 조건과 함께 선택하십시오.
A36: 측정 각도 | B36: 기본값은 정상입사 0°입니다. CM-36dG d:8의 8°는 관찰각이므로 입사각으로 자동 적용하지 않았습니다.
A37: 극값 처리 | B37: 설정한 검색 구간의 전역 최소/최대를 사용하며, 동일한 극값이 여러 파장에 있으면 그 파장의 평균을 사용합니다. 원본 분해능은 10 nm입니다.
A38: 데이터 가정 | B38: TMM은 굴절률 실수부 n, 정상입사, 투명·비흡수 막, 반무한 PET를 가정합니다. PET 후면 반사와 k는 포함하지 않습니다.

Sheet Nb2O5 입력
A2: Nb2O5 (1L) 반사율 입력
A3: CM-36dG 원본 13개 행(A:AT)을 노란색 영역에 붙여넣으면 극값과 두께가 자동 계산됩니다.
A5: 시료 | B5: Data Name | C5: L*(D65) | D5: a*(D65) | E5: b*(D65) | F5: Y(D65) | G5: Group Traits | H5: 360 | I5: 370 | J5: 380 | K5: 390 | L5: 400 | M5: 410 | N5: 420 | O5: 430 | P5: 440 | Q5: 450 | R5: 460 | S5: 470 | T5: 480 | U5: 490 | V5: 500 | W5: 510 | X5: 520 | Y5: 530 | Z5: 540 | AA5: 550 | AB5: 560 | AC5: 570 | AD5: 580 | AE5: 590 | AF5: 600 | AG5: 610 | AH5: 620 | AI5: 630 | AJ5: 640 | AK5: 650 | AL5: 660 | AM5: 670 | AN5: 680 | AO5: 690 | AP5: 700 | AQ5: 710 | AR5: 720 | AS5: 730 | AT5: 740 | AU5: 최소 R(%) | AV5: 최소 λ(nm) | AW5: 최대 R(%) | AX5: 최대 λ(nm) | AY5: 수동 λ(nm) | AZ5: 사용 λ(nm) | BA5: 굴절률 n | BB5: cosθf | BC5: Nb2O5 추정 두께(nm) | BD5: 상태 | BE5: 360 | BF5: 370 | BG5: 380 | BH5: 390 | BI5: 400 | BJ5: 410 | BK5: 420 | BL5: 430 | BM5: 440 | BN5: 450 | BO5: 460 | BP5: 470 | BQ5: 480 | BR5: 490 | BS5: 500 | BT5: 510 | BU5: 520 | BV5: 530 | BW5: 540 | BX5: 550 | BY5: 560 | BZ5: 570 | CA5: 580 | CB5: 590 | CC5: 600 | CD5: 610 | CE5: 620 | CF5: 630 | CG5: 640 | CH5: 650 | CI5: 660 | CJ5: 670 | CK5: 680 | CL5: 690 | CM5: 700 | CN5: 710 | CO5: 720 | CP5: 730 | CQ5: 740
A6: 1 | B6: Nb2O5 균일도_01 | C6: 49.66 | D6: 9.32 | E6: 9.15 | F6: 18.14 | G6: SCI | H6: 36.64 | I6: 33.94 | J6: 30.67 | K6: 27.27 | L6: 23.93 | M6: 20.79 | N6: 18.06 | O6: 15.96 | P6: 14.28 | Q6: 13.24 | R6: 12.54 | S6: 12.34 | T6: 12.48 | U6: 12.85 | V6: 13.51 | W6: 14.22 | X6: 15.1 | Y6: 15.99 | Z6: 16.97 | AA6: 17.9 | AB6: 18.86 | AC6: 19.78 | AD6: 20.64 | AE6: 21.49 | AF6: 22.28 | AG6: 23.02 | AH6: 23.73 | AI6: 24.33 | AJ6: 24.97 | AK6: 25.46 | AL6: 26 | AM6: 26.47 | AN6: 26.86 | AO6: 27.24 | AP6: 27.6 | AQ6: 27.91 | AR6: 28.11 | AS6: 28.44 | AT6: 28.64 | AU6: =IF(OR(설정!$E$7>설정!$F$7,COUNT(H6:AT6)=0),"",MIN(BE6:CQ6)) -> 12.34 | AV6: =IF(AU6="","",SUMIFS($BE$5:$CQ$5,BE6:CQ6,AU6)/COUNTIFS(BE6:CQ6,AU6)) -> 470 | AW6: =IF(OR(설정!$E$7>설정!$F$7,COUNT(H6:AT6)=0),"",MAX(BE6:CQ6)) -> 22.28 | AX6: =IF(AW6="","",SUMIFS($BE$5:$CQ$5,BE6:CQ6,AW6)/COUNTIFS(BE6:CQ6,AW6)) -> 600 | AZ6: =IF(AY6<>"",AY6,IF(설정!$C$7="최소",AV6,AX6)) -> 470 | BA6: =IF(AZ6="","",IF(OR(AZ6<굴절률!$A$6,AZ6>굴절률!$A$44),"",IF(COUNTIFS(굴절률!$A$6:$A$44,AZ6)>0,INDEX(굴절률!$C$6:$C$44,MATCH(AZ6,굴절률!$A$6:$A$44,0)),INDEX(굴절률!$C$6:$C$44,MATCH(AZ6,굴절률!$A$6:$A$44,1))+(AZ6-INDEX(굴절률!$A$6:$A$44,MATCH(AZ6,굴절률!$A$6:$A$44,1)))*(INDEX(굴절률!$C$6:$C$44,MATCH(AZ6,굴절률!$A$6:$A$44,1)+1)-INDEX(굴절률!$C$6:$C$44,MATCH(AZ6,굴절률!$A$6:$A$44,1)))/(INDEX(굴절률!$A$6:$A$44,MATCH(AZ6,굴절률!$A$6:$A$44,1)+1)-INDEX(굴절률!$A$6:$A$44,MATCH(AZ6,굴절률!$A$6:$A$44,1)))))) -> 2.36641 | BB6: =IF(BA6="","",COS(ASIN(SIN(RADIANS(설정!$G$7))/BA6))) -> 1 | BC6: =IF(OR(AZ6="",BA6="",BB6=""),"",IF(설정!$C$7="최소",설정!$D$7*AZ6/(2*BA6*BB6),(2*설정!$D$7-1)*AZ6/(4*BA6*BB6))) -> 99.306545 | BD6: =IF(COUNT(H6:AT6)=0,"입력 필요",IF(COUNT(H6:AT6)<>39,"데이터 점검",IF(OR(설정!$E$7>설정!$F$7,설정!$E$7<360,설정!$F$7>740),"검색 범위 오류",IF(AY6<>"","수동 파장",IF(OR(AZ6=설정!$E$7,AZ6=설정!$F$7),"경계 극값 확인","완료"))))) -> 완료 | BE6: =IF(AND(BE$5>=설정!$E$7,BE$5<=설정!$F$7),H6,"") | BF6: =IF(AND(BF$5>=설정!$E$7,BF$5<=설정!$F$7),I6,"") | BG6: =IF(AND(BG$5>=설정!$E$7,BG$5<=설정!$F$7),J6,"") | BH6: =IF(AND(BH$5>=설정!$E$7,BH$5<=설정!$F$7),K6,"") | BI6: =IF(AND(BI$5>=설정!$E$7,BI$5<=설정!$F$7),L6,"") | BJ6: =IF(AND(BJ$5>=설정!$E$7,BJ$5<=설정!$F$7),M6,"") | BK6: =IF(AND(BK$5>=설정!$E$7,BK$5<=설정!$F$7),N6,"") | BL6: =IF(AND(BL$5>=설정!$E$7,BL$5<=설정!$F$7),O6,"") -> 15.96 | ... CQ6: =IF(AND(CQ$5>=설정!$E$7,CQ$5<=설정!$F$7),AT6,"")
A7: 2 | B7: Nb2O5 균일도_02 | C7: 46.46 | D7: 13.28 | E7: -3.63 | F7: 15.61 | G7: SCI | H7: 36.62 | I7: 36.53 | J7: 34.91 | K7: 32.6 | L7: 29.85 | M7: 26.9 | N7: 23.96 | O7: 21.23 | P7: 18.7 | Q7: 16.81 | R7: 15.03 | S7: 13.78 | T7: 12.94 | U7: 12.46 | V7: 12.32 | W7: 12.39 | X7: 12.73 | Y7: 13.24 | Z7: 13.9 | AA7: 14.61 | AB7: 15.44 | AC7: 16.3 | AD7: 17.16 | AE7: 18 | AF7: 18.86 | AG7: 19.69 | AH7: 20.5 | AI7: 21.21 | AJ7: 21.97 | AK7: 22.63 | AL7: 23.28 | AM7: 23.85 | AN7: 24.45 | AO7: 24.96 | AP7: 25.44 | AQ7: 25.89 | AR7: 26.19 | AS7: 26.64 | AT7: 27.02 | AU7: =IF(OR(설정!$E$7>설정!$F$7,COUNT(H7:AT7)=0),"",MIN(BE7:CQ7)) -> 12.32 | AV7: =IF(AU7="","",SUMIFS($BE$5:$CQ$5,BE7:CQ7,AU7)/COUNTIFS(BE7:CQ7,AU7)) -> 500 | AW7: =IF(OR(설정!$E$7>설정!$F$7,COUNT(H7:AT7)=0),"",MAX(BE7:CQ7)) -> 21.23 | AX7: =IF(AW7="","",SUMIFS($BE$5:$CQ$5,BE7:CQ7,AW7)/COUNTIFS(BE7:CQ7,AW7)) -> 430 | AZ7: =IF(AY7<>"",AY7,IF(설정!$C$7="최소",AV7,AX7)) -> 500 | BA7: =IF(AZ7="","",IF(OR(AZ7<굴절률!$A$6,AZ7>굴절률!$A$44),"",IF(COUNTIFS(굴절률!$A$6:$A$44,AZ7)>0,INDEX(굴절률!$C$6:$C$44,MATCH(AZ7,굴절률!$A$6:$A$44,0)),INDEX(굴절률!$C$6:$C$44,MATCH(AZ7,굴절률!$A$6:$A$44,1))+(AZ7-INDEX(굴절률!$A$6:$A$44,MATCH(AZ7,굴절률!$A$6:$A$44,1)))*(INDEX(굴절률!$C$6:$C$44,MATCH(AZ7,굴절률!$A$6:$A$44,1)+1)-INDEX(굴절률!$C$6:$C$44,MATCH(AZ7,굴절률!$A$6:$A$44,1)))/(INDEX(굴절률!$A$6:$A$44,MATCH(AZ7,굴절률!$A$6:$A$44,1)+1)-INDEX(굴절률!$A$6:$A$44,MATCH(AZ7,굴절률!$A$6:$A$44,1)))))) -> 2.3457 | BB7: =IF(BA7="","",COS(ASIN(SIN(RADIANS(설정!$G$7))/BA7))) -> 1 | BC7: =IF(OR(AZ7="",BA7="",BB7=""),"",IF(설정!$C$7="최소",설정!$D$7*AZ7/(2*BA7*BB7),(2*설정!$D$7-1)*AZ7/(4*BA7*BB7))) -> 106.57799 | BD7: =IF(COUNT(H7:AT7)=0,"입력 필요",IF(COUNT(H7:AT7)<>39,"데이터 점검",IF(OR(설정!$E$7>설정!$F$7,설정!$E$7<360,설정!$F$7>740),"검색 범위 오류",IF(AY7<>"","수동 파장",IF(OR(AZ7=설정!$E$7,AZ7=설정!$F$7),"경계 극값 확인","완료"))))) -> 완료 | BE7: =IF(AND(BE$5>=설정!$E$7,BE$5<=설정!$F$7),H7,"") | BF7: =IF(AND(BF$5>=설정!$E$7,BF$5<=설정!$F$7),I7,"") | BG7: =IF(AND(BG$5>=설정!$E$7,BG$5<=설정!$F$7),J7,"") | BH7: =IF(AND(BH$5>=설정!$E$7,BH$5<=설정!$F$7),K7,"") | BI7: =IF(AND(BI$5>=설정!$E$7,BI$5<=설정!$F$7),L7,"") | BJ7: =IF(AND(BJ$5>=설정!$E$7,BJ$5<=설정!$F$7),M7,"") | BK7: =IF(AND(BK$5>=설정!$E$7,BK$5<=설정!$F$7),N7,"") | BL7: =IF(AND(BL$5>=설정!$E$7,BL$5<=설정!$F$7),O7,"") -> 21.23 | ... CQ7: =IF(AND(CQ$5>=설정!$E$7,CQ$5<=설정!$F$7),AT7,"")
A8: 3 | B8: Nb2O5 균일도_03 | C8: 45.35 | D8: 14.16 | E8: -9.52 | F8: 14.79 | G8: SCI | H8: 35.1 | I8: 36.37 | J8: 35.66 | K8: 34.11 | L8: 31.87 | M8: 29.2 | N8: 26.48 | O8: 23.82 | P8: 21.13 | Q8: 18.94 | R8: 16.85 | S8: 15.29 | T8: 13.95 | U8: 13.1 | V8: 12.52 | W8: 12.24 | X8: 12.27 | Y8: 12.5 | Z8: 12.93 | AA8: 13.46 | AB8: 14.13 | AC8: 14.88 | AD8: 15.67 | AE8: 16.47 | AF8: 17.32 | AG8: 18.14 | AH8: 18.94 | AI8: 19.69 | AJ8: 20.47 | AK8: 21.17 | AL8: 21.89 | AM8: 22.5 | AN8: 23.09 | AO8: 23.7 | AP8: 24.24 | AQ8: 24.75 | AR8: 25.14 | AS8: 25.63 | AT8: 26.04 | AU8: =IF(OR(설정!$E$7>설정!$F$7,COUNT(H8:AT8)=0),"",MIN(BE8:CQ8)) -> 12.24 | AV8: =IF(AU8="","",SUMIFS($BE$5:$CQ$5,BE8:CQ8,AU8)/COUNTIFS(BE8:CQ8,AU8)) -> 510 | AW8: =IF(OR(설정!$E$7>설정!$F$7,COUNT(H8:AT8)=0),"",MAX(BE8:CQ8)) -> 23.82 | AX8: =IF(AW8="","",SUMIFS($BE$5:$CQ$5,BE8:CQ8,AW8)/COUNTIFS(BE8:CQ8,AW8)) -> 430 | AZ8: =IF(AY8<>"",AY8,IF(설정!$C$7="최소",AV8,AX8)) -> 510 | BA8: =IF(AZ8="","",IF(OR(AZ8<굴절률!$A$6,AZ8>굴절률!$A$44),"",IF(COUNTIFS(굴절률!$A$6:$A$44,AZ8)>0,INDEX(굴절률!$C$6:$C$44,MATCH(AZ8,굴절률!$A$6:$A$44,0)),INDEX(굴절률!$C$6:$C$44,MATCH(AZ8,굴절률!$A$6:$A$44,1))+(AZ8-INDEX(굴절률!$A$6:$A$44,MATCH(AZ8,굴절률!$A$6:$A$44,1)))*(INDEX(굴절률!$C$6:$C$44,MATCH(AZ8,굴절률!$A$6:$A$44,1)+1)-INDEX(굴절률!$C$6:$C$44,MATCH(AZ8,굴절률!$A$6:$A$44,1)))/(INDEX(굴절률!$A$6:$A$44,MATCH(AZ8,굴절률!$A$6:$A$44,1)+1)-INDEX(굴절률!$A$6:$A$44,MATCH(AZ8,굴절률!$A$6:$A$44,1)))))) -> 2.33996 | BB8: =IF(BA8="","",COS(ASIN(SIN(RADIANS(설정!$G$7))/BA8))) -> 1 | BC8: =IF(OR(AZ8="",BA8="",BB8=""),"",IF(설정!$C$7="최소",설정!$D$7*AZ8/(2*BA8*BB8),(2*설정!$D$7-1)*AZ8/(4*BA8*BB8))) -> 108.97622 | BD8: =IF(COUNT(H8:AT8)=0,"입력 필요",IF(COUNT(H8:AT8)<>39,"데이터 점검",IF(OR(설정!$E$7>설정!$F$7,설정!$E$7<360,설정!$F$7>740),"검색 범위 오류",IF(AY8<>"","수동 파장",IF(OR(AZ8=설정!$E$7,AZ8=설정!$F$7),"경계 극값 확인","완료"))))) -> 완료 | BE8: =IF(AND(BE$5>=설정!$E$7,BE$5<=설정!$F$7),H8,"") | BF8: =IF(AND(BF$5>=설정!$E$7,BF$5<=설정!$F$7),I8,"") | BG8: =IF(AND(BG$5>=설정!$E$7,BG$5<=설정!$F$7),J8,"") | BH8: =IF(AND(BH$5>=설정!$E$7,BH$5<=설정!$F$7),K8,"") | BI8: =IF(AND(BI$5>=설정!$E$7,BI$5<=설정!$F$7),L8,"") | BJ8: =IF(AND(BJ$5>=설정!$E$7,BJ$5<=설정!$F$7),M8,"") | BK8: =IF(AND(BK$5>=설정!$E$7,BK$5<=설정!$F$7),N8,"") | BL8: =IF(AND(BL$5>=설정!$E$7,BL$5<=설정!$F$7),O8,"") -> 23.82 | ... CQ8: =IF(AND(CQ$5>=설정!$E$7,CQ$5<=설정!$F$7),AT8,"")
A9: 4 | B9: Nb2O5 균일도_04 | C9: 44.81 | D9: 14.26 | E9: -13.04 | F9: 14.41 | G9: SCI | H9: 33.68 | I9: 35.85 | J9: 35.82 | K9: 34.78 | L9: 32.93 | M9: 30.54 | N9: 28.02 | O9: 25.4 | P9: 22.68 | Q9: 20.46 | R9: 18.21 | S9: 16.44 | T9: 14.85 | U9: 13.74 | V9: 12.92 | W9: 12.4 | X9: 12.19 | Y9: 12.24 | Z9: 12.5 | AA9: 12.89 | AB9: 13.43 | AC9: 14.08 | AD9: 14.8 | AE9: 15.55 | AF9: 16.35 | AG9: 17.14 | AH9: 17.96 | AI9: 18.69 | AJ9: 19.49 | AK9: 20.19 | AL9: 20.93 | AM9: 21.59 | AN9: 22.22 | AO9: 22.8 | AP9: 23.4 | AQ9: 23.94 | AR9: 24.36 | AS9: 24.89 | AT9: 25.29 | AU9: =IF(OR(설정!$E$7>설정!$F$7,COUNT(H9:AT9)=0),"",MIN(BE9:CQ9)) -> 12.19 | AV9: =IF(AU9="","",SUMIFS($BE$5:$CQ$5,BE9:CQ9,AU9)/COUNTIFS(BE9:CQ9,AU9)) -> 520 | AW9: =IF(OR(설정!$E$7>설정!$F$7,COUNT(H9:AT9)=0),"",MAX(BE9:CQ9)) -> 25.4 | AX9: =IF(AW9="","",SUMIFS($BE$5:$CQ$5,BE9:CQ9,AW9)/COUNTIFS(BE9:CQ9,AW9)) -> 430 | AZ9: =IF(AY9<>"",AY9,IF(설정!$C$7="최소",AV9,AX9)) -> 520 | BA9: =IF(AZ9="","",IF(OR(AZ9<굴절률!$A$6,AZ9>굴절률!$A$44),"",IF(COUNTIFS(굴절률!$A$6:$A$44,AZ9)>0,INDEX(굴절률!$C$6:$C$44,MATCH(AZ9,굴절률!$A$6:$A$44,0)),INDEX(굴절률!$C$6:$C$44,MATCH(AZ9,굴절률!$A$6:$A$44,1))+(AZ9-INDEX(굴절률!$A$6:$A$44,MATCH(AZ9,굴절률!$A$6:$A$44,1)))*(INDEX(굴절률!$C$6:$C$44,MATCH(AZ9,굴절률!$A$6:$A$44,1)+1)-INDEX(굴절률!$C$6:$C$44,MATCH(AZ9,굴절률!$A$6:$A$44,1)))/(INDEX(굴절률!$A$6:$A$44,MATCH(AZ9,굴절률!$A$6:$A$44,1)+1)-INDEX(굴절률!$A$6:$A$44,MATCH(AZ9,굴절률!$A$6:$A$44,1)))))) -> 2.33468 | BB9: =IF(BA9="","",COS(ASIN(SIN(RADIANS(설정!$G$7))/BA9))) -> 1 | BC9: =IF(OR(AZ9="",BA9="",BB9=""),"",IF(설정!$C$7="최소",설정!$D$7*AZ9/(2*BA9*BB9),(2*설정!$D$7-1)*AZ9/(4*BA9*BB9))) -> 111.3643 | BD9: =IF(COUNT(H9:AT9)=0,"입력 필요",IF(COUNT(H9:AT9)<>39,"데이터 점검",IF(OR(설정!$E$7>설정!$F$7,설정!$E$7<360,설정!$F$7>740),"검색 범위 오류",IF(AY9<>"","수동 파장",IF(OR(AZ9=설정!$E$7,AZ9=설정!$F$7),"경계 극값 확인","완료"))))) -> 완료 | BE9: =IF(AND(BE$5>=설정!$E$7,BE$5<=설정!$F$7),H9,"") | BF9: =IF(AND(BF$5>=설정!$E$7,BF$5<=설정!$F$7),I9,"") | BG9: =IF(AND(BG$5>=설정!$E$7,BG$5<=설정!$F$7),J9,"") | BH9: =IF(AND(BH$5>=설정!$E$7,BH$5<=설정!$F$7),K9,"") | BI9: =IF(AND(BI$5>=설정!$E$7,BI$5<=설정!$F$7),L9,"") | BJ9: =IF(AND(BJ$5>=설정!$E$7,BJ$5<=설정!$F$7),M9,"") | BK9: =IF(AND(BK$5>=설정!$E$7,BK$5<=설정!$F$7),N9,"") | BL9: =IF(AND(BL$5>=설정!$E$7,BL$5<=설정!$F$7),O9,"") -> 25.4 | ... CQ9: =IF(AND(CQ$5>=설정!$E$7,CQ$5<=설정!$F$7),AT9,"")
A10: 5 | B10: Nb2O5 균일도_05 | C10: 44.67 | D10: 14.13 | E10: -14.66 | F10: 14.3 | G10: SCI | H10: 32.87 | I10: 35.49 | J10: 35.83 | K10: 35.04 | L10: 33.4 | M10: 31.17 | N10: 28.74 | O10: 26.23 | P10: 23.53 | Q10: 21.25 | R10: 18.95 | S10: 17.1 | T10: 15.43 | U10: 14.2 | V10: 13.23 | W10: 12.61 | X10: 12.28 | Y10: 12.22 | Z10: 12.38 | AA10: 12.68 | AB10: 13.16 | AC10: 13.76 | AD10: 14.43 | AE10: 15.16 | AF10: 15.93 | AG10: 16.72 | AH10: 17.51 | AI10: 18.24 | AJ10: 19.06 | AK10: 19.76 | AL10: 20.49 | AM10: 21.16 | AN10: 21.8 | AO10: 22.43 | AP10: 23 | AQ10: 23.55 | AR10: 23.97 | AS10: 24.55 | AT10: 25.02 | AU10: =IF(OR(설정!$E$7>설정!$F$7,COUNT(H10:AT10)=0),"",MIN(BE10:CQ10)) -> 12.22 | AV10: =IF(AU10="","",SUMIFS($BE$5:$CQ$5,BE10:CQ10,AU10)/COUNTIFS(BE10:CQ10,AU10)) -> 530 | AW10: =IF(OR(설정!$E$7>설정!$F$7,COUNT(H10:AT10)=0),"",MAX(BE10:CQ10)) -> 26.23 | AX10: =IF(AW10="","",SUMIFS($BE$5:$CQ$5,BE10:CQ10,AW10)/COUNTIFS(BE10:CQ10,AW10)) -> 430 | AZ10: =IF(AY10<>"",AY10,IF(설정!$C$7="최소",AV10,AX10)) -> 530 | BA10: =IF(AZ10="","",IF(OR(AZ10<굴절률!$A$6,AZ10>굴절률!$A$44),"",IF(COUNTIFS(굴절률!$A$6:$A$44,AZ10)>0,INDEX(굴절률!$C$6:$C$44,MATCH(AZ10,굴절률!$A$6:$A$44,0)),INDEX(굴절률!$C$6:$C$44,MATCH(AZ10,굴절률!$A$6:$A$44,1))+(AZ10-INDEX(굴절률!$A$6:$A$44,MATCH(AZ10,굴절률!$A$6:$A$44,1)))*(INDEX(굴절률!$C$6:$C$44,MATCH(AZ10,굴절률!$A$6:$A$44,1)+1)-INDEX(굴절률!$C$6:$C$44,MATCH(AZ10,굴절률!$A$6:$A$44,1)))/(INDEX(굴절률!$A$6:$A$44,MATCH(AZ10,굴절률!$A$6:$A$44,1)+1)-INDEX(굴절률!$A$6:$A$44,MATCH(AZ10,굴절률!$A$6:$A$44,1)))))) -> 2.32981 | BB10: =IF(BA10="","",COS(ASIN(SIN(RADIANS(설정!$G$7))/BA10))) -> 1 | BC10: =IF(OR(AZ10="",BA10="",BB10=""),"",IF(설정!$C$7="최소",설정!$D$7*AZ10/(2*BA10*BB10),(2*설정!$D$7-1)*AZ10/(4*BA10*BB10))) -> 113.74318 | BD10: =IF(COUNT(H10:AT10)=0,"입력 필요",IF(COUNT(H10:AT10)<>39,"데이터 점검",IF(OR(설정!$E$7>설정!$F$7,설정!$E$7<360,설정!$F$7>740),"검색 범위 오류",IF(AY10<>"","수동 파장",IF(OR(AZ10=설정!$E$7,AZ10=설정!$F$7),"경계 극값 확인","완료"))))) -> 완료 | BE10: =IF(AND(BE$5>=설정!$E$7,BE$5<=설정!$F$7),H10,"") | BF10: =IF(AND(BF$5>=설정!$E$7,BF$5<=설정!$F$7),I10,"") | BG10: =IF(AND(BG$5>=설정!$E$7,BG$5<=설정!$F$7),J10,"") | BH10: =IF(AND(BH$5>=설정!$E$7,BH$5<=설정!$F$7),K10,"") | BI10: =IF(AND(BI$5>=설정!$E$7,BI$5<=설정!$F$7),L10,"") | BJ10: =IF(AND(BJ$5>=설정!$E$7,BJ$5<=설정!$F$7),M10,"") | BK10: =IF(AND(BK$5>=설정!$E$7,BK$5<=설정!$F$7),N10,"") | BL10: =IF(AND(BL$5>=설정!$E$7,BL$5<=설정!$F$7),O10,"") -> 26.23 | ... CQ10: =IF(AND(CQ$5>=설정!$E$7,CQ$5<=설정!$F$7),AT10,"")
A11: 6 | B11: Nb2O5 균일도_06 | C11: 44.77 | D11: 14.18 | E11: -13.36 | F11: 14.37 | G11: SCI | H11: 33.37 | I11: 35.66 | J11: 35.74 | K11: 34.73 | L11: 32.97 | M11: 30.64 | N11: 28.05 | O11: 25.53 | P11: 22.85 | Q11: 20.62 | R11: 18.34 | S11: 16.55 | T11: 14.94 | U11: 13.87 | V11: 12.99 | W11: 12.46 | X11: 12.22 | Y11: 12.24 | Z11: 12.45 | AA11: 12.83 | AB11: 13.37 | AC11: 14.01 | AD11: 14.71 | AE11: 15.46 | AF11: 16.24 | AG11: 17.04 | AH11: 17.81 | AI11: 18.58 | AJ11: 19.36 | AK11: 20.07 | AL11: 20.8 | AM11: 21.44 | AN11: 22.08 | AO11: 22.68 | AP11: 23.24 | AQ11: 23.79 | AR11: 24.21 | AS11: 24.72 | AT11: 25.21 | AU11: =IF(OR(설정!$E$7>설정!$F$7,COUNT(H11:AT11)=0),"",MIN(BE11:CQ11)) -> 12.22 | AV11: =IF(AU11="","",SUMIFS($BE$5:$CQ$5,BE11:CQ11,AU11)/COUNTIFS(BE11:CQ11,AU11)) -> 520 | AW11: =IF(OR(설정!$E$7>설정!$F$7,COUNT(H11:AT11)=0),"",MAX(BE11:CQ11)) -> 25.53 | AX11: =IF(AW11="","",SUMIFS($BE$5:$CQ$5,BE11:CQ11,AW11)/COUNTIFS(BE11:CQ11,AW11)) -> 430 | AZ11: =IF(AY11<>"",AY11,IF(설정!$C$7="최소",AV11,AX11)) -> 520 | BA11: =IF(AZ11="","",IF(OR(AZ11<굴절률!$A$6,AZ11>굴절률!$A$44),"",IF(COUNTIFS(굴절률!$A$6:$A$44,AZ11)>0,INDEX(굴절률!$C$6:$C$44,MATCH(AZ11,굴절률!$A$6:$A$44,0)),INDEX(굴절률!$C$6:$C$44,MATCH(AZ11,굴절률!$A$6:$A$44,1))+(AZ11-INDEX(굴절률!$A$6:$A$44,MATCH(AZ11,굴절률!$A$6:$A$44,1)))*(INDEX(굴절률!$C$6:$C$44,MATCH(AZ11,굴절률!$A$6:$A$44,1)+1)-INDEX(굴절률!$C$6:$C$44,MATCH(AZ11,굴절률!$A$6:$A$44,1)))/(INDEX(굴절률!$A$6:$A$44,MATCH(AZ11,굴절률!$A$6:$A$44,1)+1)-INDEX(굴절률!$A$6:$A$44,MATCH(AZ11,굴절률!$A$6:$A$44,1)))))) -> 2.33468 | BB11: =IF(BA11="","",COS(ASIN(SIN(RADIANS(설정!$G$7))/BA11))) -> 1 | BC11: =IF(OR(AZ11="",BA11="",BB11=""),"",IF(설정!$C$7="최소",설정!$D$7*AZ11/(2*BA11*BB11),(2*설정!$D$7-1)*AZ11/(4*BA11*BB11))) -> 111.3643 | BD11: =IF(COUNT(H11:AT11)=0,"입력 필요",IF(COUNT(H11:AT11)<>39,"데이터 점검",IF(OR(설정!$E$7>설정!$F$7,설정!$E$7<360,설정!$F$7>740),"검색 범위 오류",IF(AY11<>"","수동 파장",IF(OR(AZ11=설정!$E$7,AZ11=설정!$F$7),"경계 극값 확인","완료"))))) -> 완료 | BE11: =IF(AND(BE$5>=설정!$E$7,BE$5<=설정!$F$7),H11,"") | BF11: =IF(AND(BF$5>=설정!$E$7,BF$5<=설정!$F$7),I11,"") | BG11: =IF(AND(BG$5>=설정!$E$7,BG$5<=설정!$F$7),J11,"") | BH11: =IF(AND(BH$5>=설정!$E$7,BH$5<=설정!$F$7),K11,"") | BI11: =IF(AND(BI$5>=설정!$E$7,BI$5<=설정!$F$7),L11,"") | BJ11: =IF(AND(BJ$5>=설정!$E$7,BJ$5<=설정!$F$7),M11,"") | BK11: =IF(AND(BK$5>=설정!$E$7,BK$5<=설정!$F$7),N11,"") | BL11: =IF(AND(BL$5>=설정!$E$7,BL$5<=설정!$F$7),O11,"") -> 25.53 | ... CQ11: =IF(AND(CQ$5>=설정!$E$7,CQ$5<=설정!$F$7),AT11,"")
A12: 7 | B12: Nb2O5 균일도_07 | C12: 45.07 | D12: 14.16 | E12: -10.45 | F12: 14.59 | G12: SCI | H12: 34.57 | I12: 36.08 | J12: 35.58 | K12: 34.14 | L12: 32.04 | M12: 29.44 | N12: 26.72 | O12: 24.12 | P12: 21.43 | Q12: 19.17 | R12: 17.13 | S12: 15.48 | T12: 14.08 | U12: 13.19 | V12: 12.53 | W12: 12.22 | X12: 12.16 | Y12: 12.34 | Z12: 12.72 | AA12: 13.21 | AB12: 13.87 | AC12: 14.59 | AD12: 15.35 | AE12: 16.14 | AF12: 16.95 | AG12: 17.74 | AH12: 18.55 | AI12: 19.29 | AJ12: 20.08 | AK12: 20.76 | AL12: 21.48 | AM12: 22.14 | AN12: 22.72 | AO12: 23.3 | AP12: 23.79 | AQ12: 24.29 | AR12: 24.71 | AS12: 25.21 | AT12: 25.63 | AU12: =IF(OR(설정!$E$7>설정!$F$7,COUNT(H12:AT12)=0),"",MIN(BE12:CQ12)) -> 12.16 | AV12: =IF(AU12="","",SUMIFS($BE$5:$CQ$5,BE12:CQ12,AU12)/COUNTIFS(BE12:CQ12,AU12)) -> 520 | AW12: =IF(OR(설정!$E$7>설정!$F$7,COUNT(H12:AT12)=0),"",MAX(BE12:CQ12)) -> 24.12 | AX12: =IF(AW12="","",SUMIFS($BE$5:$CQ$5,BE12:CQ12,AW12)/COUNTIFS(BE12:CQ12,AW12)) -> 430 | AZ12: =IF(AY12<>"",AY12,IF(설정!$C$7="최소",AV12,AX12)) -> 520 | BA12: =IF(AZ12="","",IF(OR(AZ12<굴절률!$A$6,AZ12>굴절률!$A$44),"",IF(COUNTIFS(굴절률!$A$6:$A$44,AZ12)>0,INDEX(굴절률!$C$6:$C$44,MATCH(AZ12,굴절률!$A$6:$A$44,0)),INDEX(굴절률!$C$6:$C$44,MATCH(AZ12,굴절률!$A$6:$A$44,1))+(AZ12-INDEX(굴절률!$A$6:$A$44,MATCH(AZ12,굴절률!$A$6:$A$44,1)))*(INDEX(굴절률!$C$6:$C$44,MATCH(AZ12,굴절률!$A$6:$A$44,1)+1)-INDEX(굴절률!$C$6:$C$44,MATCH(AZ12,굴절률!$A$6:$A$44,1)))/(INDEX(굴절률!$A$6:$A$44,MATCH(AZ12,굴절률!$A$6:$A$44,1)+1)-INDEX(굴절률!$A$6:$A$44,MATCH(AZ12,굴절률!$A$6:$A$44,1)))))) -> 2.33468 | BB12: =IF(BA12="","",COS(ASIN(SIN(RADIANS(설정!$G$7))/BA12))) -> 1 | BC12: =IF(OR(AZ12="",BA12="",BB12=""),"",IF(설정!$C$7="최소",설정!$D$7*AZ12/(2*BA12*BB12),(2*설정!$D$7-1)*AZ12/(4*BA12*BB12))) -> 111.3643 | BD12: =IF(COUNT(H12:AT12)=0,"입력 필요",IF(COUNT(H12:AT12)<>39,"데이터 점검",IF(OR(설정!$E$7>설정!$F$7,설정!$E$7<360,설정!$F$7>740),"검색 범위 오류",IF(AY12<>"","수동 파장",IF(OR(AZ12=설정!$E$7,AZ12=설정!$F$7),"경계 극값 확인","완료"))))) -> 완료 | BE12: =IF(AND(BE$5>=설정!$E$7,BE$5<=설정!$F$7),H12,"") | BF12: =IF(AND(BF$5>=설정!$E$7,BF$5<=설정!$F$7),I12,"") | BG12: =IF(AND(BG$5>=설정!$E$7,BG$5<=설정!$F$7),J12,"") | BH12: =IF(AND(BH$5>=설정!$E$7,BH$5<=설정!$F$7),K12,"") | BI12: =IF(AND(BI$5>=설정!$E$7,BI$5<=설정!$F$7),L12,"") | BJ12: =IF(AND(BJ$5>=설정!$E$7,BJ$5<=설정!$F$7),M12,"") | BK12: =IF(AND(BK$5>=설정!$E$7,BK$5<=설정!$F$7),N12,"") | BL12: =IF(AND(BL$5>=설정!$E$7,BL$5<=설정!$F$7),O12,"") -> 24.12 | ... CQ12: =IF(AND(CQ$5>=설정!$E$7,CQ$5<=설정!$F$7),AT12,"")
A13: 8 | B13: Nb2O5 균일도_08 | C13: 45.53 | D13: 13.76 | E13: -6.68 | F13: 14.92 | G13: SCI | H13: 35.47 | I13: 36.06 | J13: 34.92 | K13: 33.03 | L13: 30.57 | M13: 27.75 | N13: 24.93 | O13: 22.28 | P13: 19.6 | Q13: 17.58 | R13: 15.72 | S13: 14.29 | T13: 13.16 | U13: 12.54 | V13: 12.14 | W13: 12.07 | X13: 12.24 | Y13: 12.61 | Z13: 13.17 | AA13: 13.78 | AB13: 14.52 | AC13: 15.32 | AD13: 16.12 | AE13: 16.95 | AF13: 17.78 | AG13: 18.6 | AH13: 19.38 | AI13: 20.11 | AJ13: 20.86 | AK13: 21.52 | AL13: 22.18 | AM13: 22.76 | AN13: 23.35 | AO13: 23.91 | AP13: 24.39 | AQ13: 24.87 | AR13: 25.21 | AS13: 25.67 | AT13: 26.05 | AU13: =IF(OR(설정!$E$7>설정!$F$7,COUNT(H13:AT13)=0),"",MIN(BE13:CQ13)) -> 12.07 | AV13: =IF(AU13="","",SUMIFS($BE$5:$CQ$5,BE13:CQ13,AU13)/COUNTIFS(BE13:CQ13,AU13)) -> 510 | AW13: =IF(OR(설정!$E$7>설정!$F$7,COUNT(H13:AT13)=0),"",MAX(BE13:CQ13)) -> 22.28 | AX13: =IF(AW13="","",SUMIFS($BE$5:$CQ$5,BE13:CQ13,AW13)/COUNTIFS(BE13:CQ13,AW13)) -> 430 | AZ13: =IF(AY13<>"",AY13,IF(설정!$C$7="최소",AV13,AX13)) -> 510 | BA13: =IF(AZ13="","",IF(OR(AZ13<굴절률!$A$6,AZ13>굴절률!$A$44),"",IF(COUNTIFS(굴절률!$A$6:$A$44,AZ13)>0,INDEX(굴절률!$C$6:$C$44,MATCH(AZ13,굴절률!$A$6:$A$44,0)),INDEX(굴절률!$C$6:$C$44,MATCH(AZ13,굴절률!$A$6:$A$44,1))+(AZ13-INDEX(굴절률!$A$6:$A$44,MATCH(AZ13,굴절률!$A$6:$A$44,1)))*(INDEX(굴절률!$C$6:$C$44,MATCH(AZ13,굴절률!$A$6:$A$44,1)+1)-INDEX(굴절률!$C$6:$C$44,MATCH(AZ13,굴절률!$A$6:$A$44,1)))/(INDEX(굴절률!$A$6:$A$44,MATCH(AZ13,굴절률!$A$6:$A$44,1)+1)-INDEX(굴절률!$A$6:$A$44,MATCH(AZ13,굴절률!$A$6:$A$44,1)))))) -> 2.33996 | BB13: =IF(BA13="","",COS(ASIN(SIN(RADIANS(설정!$G$7))/BA13))) -> 1 | BC13: =IF(OR(AZ13="",BA13="",BB13=""),"",IF(설정!$C$7="최소",설정!$D$7*AZ13/(2*BA13*BB13),(2*설정!$D$7-1)*AZ13/(4*BA13*BB13))) -> 108.97622 | BD13: =IF(COUNT(H13:AT13)=0,"입력 필요",IF(COUNT(H13:AT13)<>39,"데이터 점검",IF(OR(설정!$E$7>설정!$F$7,설정!$E$7<360,설정!$F$7>740),"검색 범위 오류",IF(AY13<>"","수동 파장",IF(OR(AZ13=설정!$E$7,AZ13=설정!$F$7),"경계 극값 확인","완료"))))) -> 완료 | BE13: =IF(AND(BE$5>=설정!$E$7,BE$5<=설정!$F$7),H13,"") | BF13: =IF(AND(BF$5>=설정!$E$7,BF$5<=설정!$F$7),I13,"") | BG13: =IF(AND(BG$5>=설정!$E$7,BG$5<=설정!$F$7),J13,"") | BH13: =IF(AND(BH$5>=설정!$E$7,BH$5<=설정!$F$7),K13,"") | BI13: =IF(AND(BI$5>=설정!$E$7,BI$5<=설정!$F$7),L13,"") | BJ13: =IF(AND(BJ$5>=설정!$E$7,BJ$5<=설정!$F$7),M13,"") | BK13: =IF(AND(BK$5>=설정!$E$7,BK$5<=설정!$F$7),N13,"") | BL13: =IF(AND(BL$5>=설정!$E$7,BL$5<=설정!$F$7),O13,"") -> 22.28 | ... CQ13: =IF(AND(CQ$5>=설정!$E$7,CQ$5<=설정!$F$7),AT13,"")
A14: 9 | B14: Nb2O5 균일도_09 | C14: 47.06 | D14: 12.07 | E14: 1.03 | F14: 16.06 | G14: SCI | H14: 36.63 | I14: 35.56 | J14: 33.28 | K14: 30.58 | L14: 27.58 | M14: 24.45 | N14: 21.48 | O14: 18.93 | P14: 16.66 | Q14: 14.97 | R14: 13.58 | S14: 12.71 | T14: 12.18 | U14: 12.06 | V14: 12.21 | W14: 12.55 | X14: 13.09 | Y14: 13.77 | Z14: 14.57 | AA14: 15.37 | AB14: 16.24 | AC14: 17.14 | AD14: 17.99 | AE14: 18.83 | AF14: 19.68 | AG14: 20.48 | AH14: 21.22 | AI14: 21.88 | AJ14: 22.61 | AK14: 23.19 | AL14: 23.8 | AM14: 24.3 | AN14: 24.79 | AO14: 25.3 | AP14: 25.69 | AQ14: 26.12 | AR14: 26.38 | AS14: 26.74 | AT14: 27.05 | AU14: =IF(OR(설정!$E$7>설정!$F$7,COUNT(H14:AT14)=0),"",MIN(BE14:CQ14)) -> 12.06 | AV14: =IF(AU14="","",SUMIFS($BE$5:$CQ$5,BE14:CQ14,AU14)/COUNTIFS(BE14:CQ14,AU14)) -> 490 | AW14: =IF(OR(설정!$E$7>설정!$F$7,COUNT(H14:AT14)=0),"",MAX(BE14:CQ14)) -> 19.68 | AX14: =IF(AW14="","",SUMIFS($BE$5:$CQ$5,BE14:CQ14,AW14)/COUNTIFS(BE14:CQ14,AW14)) -> 600 | AZ14: =IF(AY14<>"",AY14,IF(설정!$C$7="최소",AV14,AX14)) -> 490 | BA14: =IF(AZ14="","",IF(OR(AZ14<굴절률!$A$6,AZ14>굴절률!$A$44),"",IF(COUNTIFS(굴절률!$A$6:$A$44,AZ14)>0,INDEX(굴절률!$C$6:$C$44,MATCH(AZ14,굴절률!$A$6:$A$44,0)),INDEX(굴절률!$C$6:$C$44,MATCH(AZ14,굴절률!$A$6:$A$44,1))+(AZ14-INDEX(굴절률!$A$6:$A$44,MATCH(AZ14,굴절률!$A$6:$A$44,1)))*(INDEX(굴절률!$C$6:$C$44,MATCH(AZ14,굴절률!$A$6:$A$44,1)+1)-INDEX(굴절률!$C$6:$C$44,MATCH(AZ14,굴절률!$A$6:$A$44,1)))/(INDEX(굴절률!$A$6:$A$44,MATCH(AZ14,굴절률!$A$6:$A$44,1)+1)-INDEX(굴절률!$A$6:$A$44,MATCH(AZ14,굴절률!$A$6:$A$44,1)))))) -> 2.35198 | BB14: =IF(BA14="","",COS(ASIN(SIN(RADIANS(설정!$G$7))/BA14))) -> 1 | BC14: =IF(OR(AZ14="",BA14="",BB14=""),"",IF(설정!$C$7="최소",설정!$D$7*AZ14/(2*BA14*BB14),(2*설정!$D$7-1)*AZ14/(4*BA14*BB14))) -> 104.16755 | BD14: =IF(COUNT(H14:AT14)=0,"입력 필요",IF(COUNT(H14:AT14)<>39,"데이터 점검",IF(OR(설정!$E$7>설정!$F$7,설정!$E$7<360,설정!$F$7>740),"검색 범위 오류",IF(AY14<>"","수동 파장",IF(OR(AZ14=설정!$E$7,AZ14=설정!$F$7),"경계 극값 확인","완료"))))) -> 완료 | BE14: =IF(AND(BE$5>=설정!$E$7,BE$5<=설정!$F$7),H14,"") | BF14: =IF(AND(BF$5>=설정!$E$7,BF$5<=설정!$F$7),I14,"") | BG14: =IF(AND(BG$5>=설정!$E$7,BG$5<=설정!$F$7),J14,"") | BH14: =IF(AND(BH$5>=설정!$E$7,BH$5<=설정!$F$7),K14,"") | BI14: =IF(AND(BI$5>=설정!$E$7,BI$5<=설정!$F$7),L14,"") | BJ14: =IF(AND(BJ$5>=설정!$E$7,BJ$5<=설정!$F$7),M14,"") | BK14: =IF(AND(BK$5>=설정!$E$7,BK$5<=설정!$F$7),N14,"") | BL14: =IF(AND(BL$5>=설정!$E$7,BL$5<=설정!$F$7),O14,"") -> 18.93 | ... CQ14: =IF(AND(CQ$5>=설정!$E$7,CQ$5<=설정!$F$7),AT14,"")
A15: 10 | B15: Nb2O5 균일도_10 | C15: 48.88 | D15: 9.64 | E15: 8.15 | F15: 17.49 | G15: SCI | H15: 36.28 | I15: 33.83 | J15: 30.67 | K15: 27.36 | L15: 24.07 | M15: 20.92 | N15: 18.14 | O15: 15.98 | P15: 14.23 | Q15: 13.12 | R15: 12.35 | S15: 12.06 | T15: 12.1 | U15: 12.42 | V15: 13.02 | W15: 13.68 | X15: 14.48 | Y15: 15.38 | Z15: 16.32 | AA15: 17.21 | AB15: 18.14 | AC15: 19.04 | AD15: 19.89 | AE15: 20.72 | AF15: 21.52 | AG15: 22.25 | AH15: 22.94 | AI15: 23.54 | AJ15: 24.17 | AK15: 24.68 | AL15: 25.19 | AM15: 25.63 | AN15: 26.04 | AO15: 26.46 | AP15: 26.82 | AQ15: 27.09 | AR15: 27.29 | AS15: 27.65 | AT15: 27.85 | AU15: =IF(OR(설정!$E$7>설정!$F$7,COUNT(H15:AT15)=0),"",MIN(BE15:CQ15)) -> 12.06 | AV15: =IF(AU15="","",SUMIFS($BE$5:$CQ$5,BE15:CQ15,AU15)/COUNTIFS(BE15:CQ15,AU15)) -> 470 | AW15: =IF(OR(설정!$E$7>설정!$F$7,COUNT(H15:AT15)=0),"",MAX(BE15:CQ15)) -> 21.52 | AX15: =IF(AW15="","",SUMIFS($BE$5:$CQ$5,BE15:CQ15,AW15)/COUNTIFS(BE15:CQ15,AW15)) -> 600 | AZ15: =IF(AY15<>"",AY15,IF(설정!$C$7="최소",AV15,AX15)) -> 470 | BA15: =IF(AZ15="","",IF(OR(AZ15<굴절률!$A$6,AZ15>굴절률!$A$44),"",IF(COUNTIFS(굴절률!$A$6:$A$44,AZ15)>0,INDEX(굴절률!$C$6:$C$44,MATCH(AZ15,굴절률!$A$6:$A$44,0)),INDEX(굴절률!$C$6:$C$44,MATCH(AZ15,굴절률!$A$6:$A$44,1))+(AZ15-INDEX(굴절률!$A$6:$A$44,MATCH(AZ15,굴절률!$A$6:$A$44,1)))*(INDEX(굴절률!$C$6:$C$44,MATCH(AZ15,굴절률!$A$6:$A$44,1)+1)-INDEX(굴절률!$C$6:$C$44,MATCH(AZ15,굴절률!$A$6:$A$44,1)))/(INDEX(굴절률!$A$6:$A$44,MATCH(AZ15,굴절률!$A$6:$A$44,1)+1)-INDEX(굴절률!$A$6:$A$44,MATCH(AZ15,굴절률!$A$6:$A$44,1)))))) -> 2.36641 | BB15: =IF(BA15="","",COS(ASIN(SIN(RADIANS(설정!$G$7))/BA15))) -> 1 | BC15: =IF(OR(AZ15="",BA15="",BB15=""),"",IF(설정!$C$7="최소",설정!$D$7*AZ15/(2*BA15*BB15),(2*설정!$D$7-1)*AZ15/(4*BA15*BB15))) -> 99.306545 | BD15: =IF(COUNT(H15:AT15)=0,"입력 필요",IF(COUNT(H15:AT15)<>39,"데이터 점검",IF(OR(설정!$E$7>설정!$F$7,설정!$E$7<360,설정!$F$7>740),"검색 범위 오류",IF(AY15<>"","수동 파장",IF(OR(AZ15=설정!$E$7,AZ15=설정!$F$7),"경계 극값 확인","완료"))))) -> 완료 | BE15: =IF(AND(BE$5>=설정!$E$7,BE$5<=설정!$F$7),H15,"") | BF15: =IF(AND(BF$5>=설정!$E$7,BF$5<=설정!$F$7),I15,"") | BG15: =IF(AND(BG$5>=설정!$E$7,BG$5<=설정!$F$7),J15,"") | BH15: =IF(AND(BH$5>=설정!$E$7,BH$5<=설정!$F$7),K15,"") | BI15: =IF(AND(BI$5>=설정!$E$7,BI$5<=설정!$F$7),L15,"") | BJ15: =IF(AND(BJ$5>=설정!$E$7,BJ$5<=설정!$F$7),M15,"") | BK15: =IF(AND(BK$5>=설정!$E$7,BK$5<=설정!$F$7),N15,"") | BL15: =IF(AND(BL$5>=설정!$E$7,BL$5<=설정!$F$7),O15,"") -> 15.98 | ... CQ15: =IF(AND(CQ$5>=설정!$E$7,CQ$5<=설정!$F$7),AT15,"")
A16: 11 | B16: Nb2O5 균일도_11 | C16: 50.47 | D16: 7.55 | E16: 12.81 | F16: 18.81 | G16: SCI | H16: 35.26 | I16: 31.8 | J16: 28.14 | K16: 24.55 | L16: 21.22 | M16: 18.28 | N16: 15.84 | O16: 14.12 | P16: 12.92 | Q16: 12.29 | R16: 12.04 | S16: 12.17 | T16: 12.64 | U16: 13.26 | V16: 14.13 | W16: 14.97 | X16: 15.94 | Y16: 16.89 | Z16: 17.89 | AA16: 18.81 | AB16: 19.75 | AC16: 20.62 | AD16: 21.45 | AE16: 22.22 | AF16: 22.94 | AG16: 23.63 | AH16: 24.25 | AI16: 24.79 | AJ16: 25.35 | AK16: 25.79 | AL16: 26.22 | AM16: 26.59 | AN16: 26.97 | AO16: 27.31 | AP16: 27.58 | AQ16: 27.82 | AR16: 27.98 | AS16: 28.22 | AT16: 28.38 | AU16: =IF(OR(설정!$E$7>설정!$F$7,COUNT(H16:AT16)=0),"",MIN(BE16:CQ16)) -> 12.04 | AV16: =IF(AU16="","",SUMIFS($BE$5:$CQ$5,BE16:CQ16,AU16)/COUNTIFS(BE16:CQ16,AU16)) -> 460 | AW16: =IF(OR(설정!$E$7>설정!$F$7,COUNT(H16:AT16)=0),"",MAX(BE16:CQ16)) -> 22.94 | AX16: =IF(AW16="","",SUMIFS($BE$5:$CQ$5,BE16:CQ16,AW16)/COUNTIFS(BE16:CQ16,AW16)) -> 600 | AZ16: =IF(AY16<>"",AY16,IF(설정!$C$7="최소",AV16,AX16)) -> 460 | BA16: =IF(AZ16="","",IF(OR(AZ16<굴절률!$A$6,AZ16>굴절률!$A$44),"",IF(COUNTIFS(굴절률!$A$6:$A$44,AZ16)>0,INDEX(굴절률!$C$6:$C$44,MATCH(AZ16,굴절률!$A$6:$A$44,0)),INDEX(굴절률!$C$6:$C$44,MATCH(AZ16,굴절률!$A$6:$A$44,1))+(AZ16-INDEX(굴절률!$A$6:$A$44,MATCH(AZ16,굴절률!$A$6:$A$44,1)))*(INDEX(굴절률!$C$6:$C$44,MATCH(AZ16,굴절률!$A$6:$A$44,1)+1)-INDEX(굴절률!$C$6:$C$44,MATCH(AZ16,굴절률!$A$6:$A$44,1)))/(INDEX(굴절률!$A$6:$A$44,MATCH(AZ16,굴절률!$A$6:$A$44,1)+1)-INDEX(굴절률!$A$6:$A$44,MATCH(AZ16,굴절률!$A$6:$A$44,1)))))) -> 2.37476 | BB16: =IF(BA16="","",COS(ASIN(SIN(RADIANS(설정!$G$7))/BA16))) -> 1 | BC16: =IF(OR(AZ16="",BA16="",BB16=""),"",IF(설정!$C$7="최소",설정!$D$7*AZ16/(2*BA16*BB16),(2*설정!$D$7-1)*AZ16/(4*BA16*BB16))) -> 96.851892 | BD16: =IF(COUNT(H16:AT16)=0,"입력 필요",IF(COUNT(H16:AT16)<>39,"데이터 점검",IF(OR(설정!$E$7>설정!$F$7,설정!$E$7<360,설정!$F$7>740),"검색 범위 오류",IF(AY16<>"","수동 파장",IF(OR(AZ16=설정!$E$7,AZ16=설정!$F$7),"경계 극값 확인","완료"))))) -> 완료 | BE16: =IF(AND(BE$5>=설정!$E$7,BE$5<=설정!$F$7),H16,"") | BF16: =IF(AND(BF$5>=설정!$E$7,BF$5<=설정!$F$7),I16,"") | BG16: =IF(AND(BG$5>=설정!$E$7,BG$5<=설정!$F$7),J16,"") | BH16: =IF(AND(BH$5>=설정!$E$7,BH$5<=설정!$F$7),K16,"") | BI16: =IF(AND(BI$5>=설정!$E$7,BI$5<=설정!$F$7),L16,"") | BJ16: =IF(AND(BJ$5>=설정!$E$7,BJ$5<=설정!$F$7),M16,"") | BK16: =IF(AND(BK$5>=설정!$E$7,BK$5<=설정!$F$7),N16,"") | BL16: =IF(AND(BL$5>=설정!$E$7,BL$5<=설정!$F$7),O16,"") -> 14.12 | ... CQ16: =IF(AND(CQ$5>=설정!$E$7,CQ$5<=설정!$F$7),AT16,"")
A17: 12 | B17: Nb2O5 균일도_12 | C17: 51.53 | D17: 6.19 | E17: 15.36 | F17: 19.73 | G17: SCI | H17: 34.06 | I17: 30.1 | J17: 26.14 | K17: 22.5 | L17: 19.27 | M17: 16.56 | N17: 14.47 | O17: 13.11 | P17: 12.28 | Q17: 12 | R17: 12.1 | S17: 12.5 | T17: 13.21 | U17: 14 | V17: 14.99 | W17: 15.96 | X17: 16.97 | Y17: 17.96 | Z17: 18.98 | AA17: 19.88 | AB17: 20.81 | AC17: 21.65 | AD17: 22.45 | AE17: 23.19 | AF17: 23.88 | AG17: 24.51 | AH17: 25.09 | AI17: 25.57 | AJ17: 26.08 | AK17: 26.5 | AL17: 26.86 | AM17: 27.18 | AN17: 27.58 | AO17: 27.85 | AP17: 28.07 | AQ17: 28.24 | AR17: 28.39 | AS17: 28.64 | AT17: 28.73 | AU17: =IF(OR(설정!$E$7>설정!$F$7,COUNT(H17:AT17)=0),"",MIN(BE17:CQ17)) -> 12 | AV17: =IF(AU17="","",SUMIFS($BE$5:$CQ$5,BE17:CQ17,AU17)/COUNTIFS(BE17:CQ17,AU17)) -> 450 | AW17: =IF(OR(설정!$E$7>설정!$F$7,COUNT(H17:AT17)=0),"",MAX(BE17:CQ17)) -> 23.88 | AX17: =IF(AW17="","",SUMIFS($BE$5:$CQ$5,BE17:CQ17,AW17)/COUNTIFS(BE17:CQ17,AW17)) -> 600 | AZ17: =IF(AY17<>"",AY17,IF(설정!$C$7="최소",AV17,AX17)) -> 450 | BA17: =IF(AZ17="","",IF(OR(AZ17<굴절률!$A$6,AZ17>굴절률!$A$44),"",IF(COUNTIFS(굴절률!$A$6:$A$44,AZ17)>0,INDEX(굴절률!$C$6:$C$44,MATCH(AZ17,굴절률!$A$6:$A$44,0)),INDEX(굴절률!$C$6:$C$44,MATCH(AZ17,굴절률!$A$6:$A$44,1))+(AZ17-INDEX(굴절률!$A$6:$A$44,MATCH(AZ17,굴절률!$A$6:$A$44,1)))*(INDEX(굴절률!$C$6:$C$44,MATCH(AZ17,굴절률!$A$6:$A$44,1)+1)-INDEX(굴절률!$C$6:$C$44,MATCH(AZ17,굴절률!$A$6:$A$44,1)))/(INDEX(굴절률!$A$6:$A$44,MATCH(AZ17,굴절률!$A$6:$A$44,1)+1)-INDEX(굴절률!$A$6:$A$44,MATCH(AZ17,굴절률!$A$6:$A$44,1)))))) -> 2.38404 | BB17: =IF(BA17="","",COS(ASIN(SIN(RADIANS(설정!$G$7))/BA17))) -> 1 | BC17: =IF(OR(AZ17="",BA17="",BB17=""),"",IF(설정!$C$7="최소",설정!$D$7*AZ17/(2*BA17*BB17),(2*설정!$D$7-1)*AZ17/(4*BA17*BB17))) -> 94.377611 | BD17: =IF(COUNT(H17:AT17)=0,"입력 필요",IF(COUNT(H17:AT17)<>39,"데이터 점검",IF(OR(설정!$E$7>설정!$F$7,설정!$E$7<360,설정!$F$7>740),"검색 범위 오류",IF(AY17<>"","수동 파장",IF(OR(AZ17=설정!$E$7,AZ17=설정!$F$7),"경계 극값 확인","완료"))))) -> 완료 | BE17: =IF(AND(BE$5>=설정!$E$7,BE$5<=설정!$F$7),H17,"") | BF17: =IF(AND(BF$5>=설정!$E$7,BF$5<=설정!$F$7),I17,"") | BG17: =IF(AND(BG$5>=설정!$E$7,BG$5<=설정!$F$7),J17,"") | BH17: =IF(AND(BH$5>=설정!$E$7,BH$5<=설정!$F$7),K17,"") | BI17: =IF(AND(BI$5>=설정!$E$7,BI$5<=설정!$F$7),L17,"") | BJ17: =IF(AND(BJ$5>=설정!$E$7,BJ$5<=설정!$F$7),M17,"") | BK17: =IF(AND(BK$5>=설정!$E$7,BK$5<=설정!$F$7),N17,"") | BL17: =IF(AND(BL$5>=설정!$E$7,BL$5<=설정!$F$7),O17,"") -> 13.11 | ... CQ17: =IF(AND(CQ$5>=설정!$E$7,CQ$5<=설정!$F$7),AT17,"")
A18: 13 | B18: Nb2O5 균일도_13 | C18: 52.24 | D18: 5.53 | E18: 16.49 | F18: 20.36 | G18: SCI | H18: 33.64 | I18: 29.39 | J18: 25.3 | K18: 21.61 | L18: 18.44 | M18: 15.86 | N18: 13.94 | O18: 12.76 | P18: 12.15 | Q18: 12.04 | R18: 12.28 | S18: 12.85 | T18: 13.65 | U18: 14.53 | V18: 15.6 | W18: 16.58 | X18: 17.64 | Y18: 18.67 | Z18: 19.68 | AA18: 20.59 | AB18: 21.51 | AC18: 22.34 | AD18: 23.11 | AE18: 23.84 | AF18: 24.5 | AG18: 25.12 | AH18: 25.68 | AI18: 26.13 | AJ18: 26.63 | AK18: 26.99 | AL18: 27.4 | AM18: 27.72 | AN18: 27.96 | AO18: 28.3 | AP18: 28.47 | AQ18: 28.68 | AR18: 28.78 | AS18: 28.96 | AT18: 29.07 | AU18: =IF(OR(설정!$E$7>설정!$F$7,COUNT(H18:AT18)=0),"",MIN(BE18:CQ18)) -> 12.04 | AV18: =IF(AU18="","",SUMIFS($BE$5:$CQ$5,BE18:CQ18,AU18)/COUNTIFS(BE18:CQ18,AU18)) -> 450 | AW18: =IF(OR(설정!$E$7>설정!$F$7,COUNT(H18:AT18)=0),"",MAX(BE18:CQ18)) -> 24.5 | AX18: =IF(AW18="","",SUMIFS($BE$5:$CQ$5,BE18:CQ18,AW18)/COUNTIFS(BE18:CQ18,AW18)) -> 600 | AZ18: =IF(AY18<>"",AY18,IF(설정!$C$7="최소",AV18,AX18)) -> 450 | BA18: =IF(AZ18="","",IF(OR(AZ18<굴절률!$A$6,AZ18>굴절률!$A$44),"",IF(COUNTIFS(굴절률!$A$6:$A$44,AZ18)>0,INDEX(굴절률!$C$6:$C$44,MATCH(AZ18,굴절률!$A$6:$A$44,0)),INDEX(굴절률!$C$6:$C$44,MATCH(AZ18,굴절률!$A$6:$A$44,1))+(AZ18-INDEX(굴절률!$A$6:$A$44,MATCH(AZ18,굴절률!$A$6:$A$44,1)))*(INDEX(굴절률!$C$6:$C$44,MATCH(AZ18,굴절률!$A$6:$A$44,1)+1)-INDEX(굴절률!$C$6:$C$44,MATCH(AZ18,굴절률!$A$6:$A$44,1)))/(INDEX(굴절률!$A$6:$A$44,MATCH(AZ18,굴절률!$A$6:$A$44,1)+1)-INDEX(굴절률!$A$6:$A$44,MATCH(AZ18,굴절률!$A$6:$A$44,1)))))) -> 2.38404 | BB18: =IF(BA18="","",COS(ASIN(SIN(RADIANS(설정!$G$7))/BA18))) -> 1 | BC18: =IF(OR(AZ18="",BA18="",BB18=""),"",IF(설정!$C$7="최소",설정!$D$7*AZ18/(2*BA18*BB18),(2*설정!$D$7-1)*AZ18/(4*BA18*BB18))) -> 94.377611 | BD18: =IF(COUNT(H18:AT18)=0,"입력 필요",IF(COUNT(H18:AT18)<>39,"데이터 점검",IF(OR(설정!$E$7>설정!$F$7,설정!$E$7<360,설정!$F$7>740),"검색 범위 오류",IF(AY18<>"","수동 파장",IF(OR(AZ18=설정!$E$7,AZ18=설정!$F$7),"경계 극값 확인","완료"))))) -> 완료 | BE18: =IF(AND(BE$5>=설정!$E$7,BE$5<=설정!$F$7),H18,"") | BF18: =IF(AND(BF$5>=설정!$E$7,BF$5<=설정!$F$7),I18,"") | BG18: =IF(AND(BG$5>=설정!$E$7,BG$5<=설정!$F$7),J18,"") | BH18: =IF(AND(BH$5>=설정!$E$7,BH$5<=설정!$F$7),K18,"") | BI18: =IF(AND(BI$5>=설정!$E$7,BI$5<=설정!$F$7),L18,"") | BJ18: =IF(AND(BJ$5>=설정!$E$7,BJ$5<=설정!$F$7),M18,"") | BK18: =IF(AND(BK$5>=설정!$E$7,BK$5<=설정!$F$7),N18,"") | BL18: =IF(AND(BL$5>=설정!$E$7,BL$5<=설정!$F$7),O18,"") -> 12.76 | ... CQ18: =IF(AND(CQ$5>=설정!$E$7,CQ$5<=설정!$F$7),AT18,"")
A20: 참고: 원본의 13-1 재측정 행은 13개 본 위치 결과에서 제외했습니다.

Sheet 2층 입력
A2: Nb2O5 (1L) / SiO2 (2L) 반사율 입력
A3: CM-36dG 원본 13개 행(A:AT)을 노란색 영역에 붙여넣으면 극값과 두께가 자동 계산됩니다.
A5: 시료 | B5: Data Name | C5: L*(D65) | D5: a*(D65) | E5: b*(D65) | F5: Y(D65) | G5: Group Traits | H5: 360 | I5: 370 | J5: 380 | K5: 390 | L5: 400 | M5: 410 | N5: 420 | O5: 430 | P5: 440 | Q5: 450 | R5: 460 | S5: 470 | T5: 480 | U5: 490 | V5: 500 | W5: 510 | X5: 520 | Y5: 530 | Z5: 540 | AA5: 550 | AB5: 560 | AC5: 570 | AD5: 580 | AE5: 590 | AF5: 600 | AG5: 610 | AH5: 620 | AI5: 630 | AJ5: 640 | AK5: 650 | AL5: 660 | AM5: 670 | AN5: 680 | AO5: 690 | AP5: 700 | AQ5: 710 | AR5: 720 | AS5: 730 | AT5: 740 | AU5: 최소 R(%) | AV5: 최소 λ(nm) | AW5: 최대 R(%) | AX5: 최대 λ(nm) | AY5: 수동 λ(nm) | AZ5: 사용 λ(nm) | BA5: SiO2 n | BB5: 하부 Nb2O5(nm) | BC5: SiO2 TMM 두께(nm) | BD5: 상태 | BE5: 360 | BF5: 370 | BG5: 380 | BH5: 390 | BI5: 400 | BJ5: 410 | BK5: 420 | BL5: 430 | BM5: 440 | BN5: 450 | BO5: 460 | BP5: 470 | BQ5: 480 | BR5: 490 | BS5: 500 | BT5: 510 | BU5: 520 | BV5: 530 | BW5: 540 | BX5: 550 | BY5: 560 | BZ5: 570 | CA5: 580 | CB5: 590 | CC5: 600 | CD5: 610 | CE5: 620 | CF5: 630 | CG5: 640 | CH5: 650 | CI5: 660 | CJ5: 670 | CK5: 680 | CL5: 690 | CM5: 700 | CN5: 710 | CO5: 720 | CP5: 730 | CQ5: 740
A6: 1 | B6: SiO2 균일도_01 | C6: 32.45 | D6: 4.74 | E6: 3.36 | F6: 7.29 | G6: SCI | H6: 17.07 | I6: 14.45 | J6: 12.51 | K6: 10.86 | L6: 9.53 | M6: 8.45 | N6: 7.56 | O6: 6.94 | P6: 6.51 | Q6: 6.21 | R6: 6.03 | S6: 5.95 | T6: 5.95 | U6: 6.06 | V6: 6.19 | W6: 6.32 | X6: 6.51 | Y6: 6.72 | Z6: 6.95 | AA6: 7.16 | AB6: 7.4 | AC6: 7.64 | AD6: 7.87 | AE6: 8.09 | AF6: 8.33 | AG6: 8.57 | AH6: 8.74 | AI6: 8.94 | AJ6: 9.17 | AK6: 9.31 | AL6: 9.53 | AM6: 9.66 | AN6: 9.84 | AO6: 10.03 | AP6: 10.17 | AQ6: 10.3 | AR6: 10.37 | AS6: 10.52 | AT6: 10.65 | AU6: =IF(OR(설정!$E$8>설정!$F$8,COUNT(H6:AT6)=0),"",MIN(BE6:CQ6)) -> 5.95 | AV6: =IF(AU6="","",SUMIFS($BE$5:$CQ$5,BE6:CQ6,AU6)/COUNTIFS(BE6:CQ6,AU6)) -> 475 | AW6: =IF(OR(설정!$E$8>설정!$F$8,COUNT(H6:AT6)=0),"",MAX(BE6:CQ6)) -> 7.16 | AX6: =IF(AW6="","",SUMIFS($BE$5:$CQ$5,BE6:CQ6,AW6)/COUNTIFS(BE6:CQ6,AW6)) -> 550 | AZ6: =IF(AY6<>"",AY6,IF(설정!$C$8="최소",AV6,AX6)) -> 475 | BA6: =IF(AZ6="","",IF(OR(AZ6<굴절률!$A$6,AZ6>굴절률!$A$44),"",IF(COUNTIFS(굴절률!$A$6:$A$44,AZ6)>0,INDEX(굴절률!$D$6:$D$44,MATCH(AZ6,굴절률!$A$6:$A$44,0)),INDEX(굴절률!$D$6:$D$44,MATCH(AZ6,굴절률!$A$6:$A$44,1))+(AZ6-INDEX(굴절률!$A$6:$A$44,MATCH(AZ6,굴절률!$A$6:$A$44,1)))*(INDEX(굴절률!$D$6:$D$44,MATCH(AZ6,굴절률!$A$6:$A$44,1)+1)-INDEX(굴절률!$D$6:$D$44,MATCH(AZ6,굴절률!$A$6:$A$44,1)))/(INDEX(굴절률!$A$6:$A$44,MATCH(AZ6,굴절률!$A$6:$A$44,1)+1)-INDEX(굴절률!$A$6:$A$44,MATCH(AZ6,굴절률!$A$6:$A$44,1)))))) -> 1.47085 | BB6: =설정!$C$16 -> 10 | BC6: =IF(OR(AZ6="",설정!$C$16="",설정!$C$16<8,설정!$C$16>15),"",IF(COUNTIFS('TMM 계산표'!$B$5:$I$5,설정!$C$16)>0,INDEX('TMM 계산표'!$B$6:$I$3806,MATCH(AZ6,'TMM 계산표'!$A$6:$A$3806,1),MATCH(설정!$C$16,'TMM 계산표'!$B$5:$I$5,0)),INDEX('TMM 계산표'!$B$6:$I$3806,MATCH(AZ6,'TMM 계산표'!$A$6:$A$3806,1),MATCH(설정!$C$16,'TMM 계산표'!$B$5:$I$5,1))+(설정!$C$16-INDEX('TMM 계산표'!$B$5:$I$5,1,MATCH(설정!$C$16,'TMM 계산표'!$B$5:$I$5,1)))*(INDEX('TMM 계산표'!$B$6:$I$3806,MATCH(AZ6,'TMM 계산표'!$A$6:$A$3806,1),MATCH(설정!$C$16,'TMM 계산표'!$B$5:$I$5,1)+1)-INDEX('TMM 계산표'!$B$6:$I$3806,MATCH(AZ6,'TMM 계산표'!$A$6:$A$3806,1),MATCH(설정!$C$16,'TMM 계산표'!$B$5:$I$5,1)))/(INDEX('TMM 계산표'!$B$5:$I$5,1,MATCH(설정!$C$16,'TMM 계산표'!$B$5:$I$5,1)+1)-INDEX('TMM 계산표'!$B$5:$I$5,1,MATCH(설정!$C$16,'TMM 계산표'!$B$5:$I$5,1))))) -> 95.324239 | BD6: =IF(COUNT(H6:AT6)=0,"입력 필요",IF(COUNT(H6:AT6)<>39,"데이터 점검",IF(OR(설정!$C$16="",설정!$C$16<8,설정!$C$16>15),"Nb 두께 입력 확인",IF(OR(설정!$E$8>설정!$F$8,설정!$E$8<360,설정!$F$8>740),"검색 범위 오류",IF(AY6<>"","수동 파장",IF(OR(AZ6=설정!$E$8,AZ6=설정!$F$8),"경계 극값 확인","완료")))))) -> 완료 | BE6: =IF(AND(BE$5>=설정!$E$8,BE$5<=설정!$F$8),H6,"") | BF6: =IF(AND(BF$5>=설정!$E$8,BF$5<=설정!$F$8),I6,"") | BG6: =IF(AND(BG$5>=설정!$E$8,BG$5<=설정!$F$8),J6,"") | BH6: =IF(AND(BH$5>=설정!$E$8,BH$5<=설정!$F$8),K6,"") | BI6: =IF(AND(BI$5>=설정!$E$8,BI$5<=설정!$F$8),L6,"") | BJ6: =IF(AND(BJ$5>=설정!$E$8,BJ$5<=설정!$F$8),M6,"") | BK6: =IF(AND(BK$5>=설정!$E$8,BK$5<=설정!$F$8),N6,"") | BL6: =IF(AND(BL$5>=설정!$E$8,BL$5<=설정!$F$8),O6,"") -> 6.94 | ... CQ6: =IF(AND(CQ$5>=설정!$E$8,CQ$5<=설정!$F$8),AT6,"")
A7: 2 | B7: SiO2 균일도_02 | C7: 31.57 | D7: 5.99 | E7: -1.01 | F7: 6.9 | G7: SCI | H7: 20.72 | I7: 17.82 | J7: 15.52 | K7: 13.51 | L7: 11.83 | M7: 10.36 | N7: 9.14 | O7: 8.2 | P7: 7.46 | Q7: 6.91 | R7: 6.5 | S7: 6.21 | T7: 6.05 | U7: 6.01 | V7: 6.01 | W7: 6.06 | X7: 6.16 | Y7: 6.3 | Z7: 6.49 | AA7: 6.66 | AB7: 6.86 | AC7: 7.09 | AD7: 7.32 | AE7: 7.52 | AF7: 7.76 | AG7: 8 | AH7: 8.2 | AI7: 8.39 | AJ7: 8.62 | AK7: 8.81 | AL7: 9.02 | AM7: 9.18 | AN7: 9.38 | AO7: 9.56 | AP7: 9.73 | AQ7: 9.88 | AR7: 10 | AS7: 10.17 | AT7: 10.29 | AU7: =IF(OR(설정!$E$8>설정!$F$8,COUNT(H7:AT7)=0),"",MIN(BE7:CQ7)) -> 6.01 | AV7: =IF(AU7="","",SUMIFS($BE$5:$CQ$5,BE7:CQ7,AU7)/COUNTIFS(BE7:CQ7,AU7)) -> 495 | AW7: =IF(OR(설정!$E$8>설정!$F$8,COUNT(H7:AT7)=0),"",MAX(BE7:CQ7)) -> 8.2 | AX7: =IF(AW7="","",SUMIFS($BE$5:$CQ$5,BE7:CQ7,AW7)/COUNTIFS(BE7:CQ7,AW7)) -> 430 | AZ7: =IF(AY7<>"",AY7,IF(설정!$C$8="최소",AV7,AX7)) -> 495 | BA7: =IF(AZ7="","",IF(OR(AZ7<굴절률!$A$6,AZ7>굴절률!$A$44),"",IF(COUNTIFS(굴절률!$A$6:$A$44,AZ7)>0,INDEX(굴절률!$D$6:$D$44,MATCH(AZ7,굴절률!$A$6:$A$44,0)),INDEX(굴절률!$D$6:$D$44,MATCH(AZ7,굴절률!$A$6:$A$44,1))+(AZ7-INDEX(굴절률!$A$6:$A$44,MATCH(AZ7,굴절률!$A$6:$A$44,1)))*(INDEX(굴절률!$D$6:$D$44,MATCH(AZ7,굴절률!$A$6:$A$44,1)+1)-INDEX(굴절률!$D$6:$D$44,MATCH(AZ7,굴절률!$A$6:$A$44,1)))/(INDEX(굴절률!$A$6:$A$44,MATCH(AZ7,굴절률!$A$6:$A$44,1)+1)-INDEX(굴절률!$A$6:$A$44,MATCH(AZ7,굴절률!$A$6:$A$44,1)))))) -> 1.47025 | BB7: =설정!$C$16 -> 10 | BC7: =IF(OR(AZ7="",설정!$C$16="",설정!$C$16<8,설정!$C$16>15),"",IF(COUNTIFS('TMM 계산표'!$B$5:$I$5,설정!$C$16)>0,INDEX('TMM 계산표'!$B$6:$I$3806,MATCH(AZ7,'TMM 계산표'!$A$6:$A$3806,1),MATCH(설정!$C$16,'TMM 계산표'!$B$5:$I$5,0)),INDEX('TMM 계산표'!$B$6:$I$3806,MATCH(AZ7,'TMM 계산표'!$A$6:$A$3806,1),MATCH(설정!$C$16,'TMM 계산표'!$B$5:$I$5,1))+(설정!$C$16-INDEX('TMM 계산표'!$B$5:$I$5,1,MATCH(설정!$C$16,'TMM 계산표'!$B$5:$I$5,1)))*(INDEX('TMM 계산표'!$B$6:$I$3806,MATCH(AZ7,'TMM 계산표'!$A$6:$A$3806,1),MATCH(설정!$C$16,'TMM 계산표'!$B$5:$I$5,1)+1)-INDEX('TMM 계산표'!$B$6:$I$3806,MATCH(AZ7,'TMM 계산표'!$A$6:$A$3806,1),MATCH(설정!$C$16,'TMM 계산표'!$B$5:$I$5,1)))/(INDEX('TMM 계산표'!$B$5:$I$5,1,MATCH(설정!$C$16,'TMM 계산표'!$B$5:$I$5,1)+1)-INDEX('TMM 계산표'!$B$5:$I$5,1,MATCH(설정!$C$16,'TMM 계산표'!$B$5:$I$5,1))))) -> 99.152109 | BD7: =IF(COUNT(H7:AT7)=0,"입력 필요",IF(COUNT(H7:AT7)<>39,"데이터 점검",IF(OR(설정!$C$16="",설정!$C$16<8,설정!$C$16>15),"Nb 두께 입력 확인",IF(OR(설정!$E$8>설정!$F$8,설정!$E$8<360,설정!$F$8>740),"검색 범위 오류",IF(AY7<>"","수동 파장",IF(OR(AZ7=설정!$E$8,AZ7=설정!$F$8),"경계 극값 확인","완료")))))) -> 완료 | BE7: =IF(AND(BE$5>=설정!$E$8,BE$5<=설정!$F$8),H7,"") | BF7: =IF(AND(BF$5>=설정!$E$8,BF$5<=설정!$F$8),I7,"") | BG7: =IF(AND(BG$5>=설정!$E$8,BG$5<=설정!$F$8),J7,"") | BH7: =IF(AND(BH$5>=설정!$E$8,BH$5<=설정!$F$8),K7,"") | BI7: =IF(AND(BI$5>=설정!$E$8,BI$5<=설정!$F$8),L7,"") | BJ7: =IF(AND(BJ$5>=설정!$E$8,BJ$5<=설정!$F$8),M7,"") | BK7: =IF(AND(BK$5>=설정!$E$8,BK$5<=설정!$F$8),N7,"") | BL7: =IF(AND(BL$5>=설정!$E$8,BL$5<=설정!$F$8),O7,"") -> 8.2 | ... CQ7: =IF(AND(CQ$5>=설정!$E$8,CQ$5<=설정!$F$8),AT7,"")
A8: 3 | B8: SiO2 균일도_03 | C8: 31.88 | D8: 5.8 | E8: -0.34 | F8: 7.03 | G8: SCI | H8: 20.47 | I8: 17.58 | J8: 15.29 | K8: 13.3 | L8: 11.64 | M8: 10.19 | N8: 8.99 | O8: 8.08 | P8: 7.39 | Q8: 6.88 | R8: 6.48 | S8: 6.25 | T8: 6.08 | U8: 6.08 | V8: 6.1 | W8: 6.16 | X8: 6.29 | Y8: 6.44 | Z8: 6.63 | AA8: 6.82 | AB8: 7.03 | AC8: 7.26 | AD8: 7.48 | AE8: 7.69 | AF8: 7.94 | AG8: 8.17 | AH8: 8.34 | AI8: 8.56 | AJ8: 8.8 | AK8: 8.95 | AL8: 9.19 | AM8: 9.33 | AN8: 9.52 | AO8: 9.7 | AP8: 9.88 | AQ8: 10.04 | AR8: 10.12 | AS8: 10.26 | AT8: 10.42 | AU8: =IF(OR(설정!$E$8>설정!$F$8,COUNT(H8:AT8)=0),"",MIN(BE8:CQ8)) -> 6.08 | AV8: =IF(AU8="","",SUMIFS($BE$5:$CQ$5,BE8:CQ8,AU8)/COUNTIFS(BE8:CQ8,AU8)) -> 485 | AW8: =IF(OR(설정!$E$8>설정!$F$8,COUNT(H8:AT8)=0),"",MAX(BE8:CQ8)) -> 8.08 | AX8: =IF(AW8="","",SUMIFS($BE$5:$CQ$5,BE8:CQ8,AW8)/COUNTIFS(BE8:CQ8,AW8)) -> 430 | AZ8: =IF(AY8<>"",AY8,IF(설정!$C$8="최소",AV8,AX8)) -> 485 | BA8: =IF(AZ8="","",IF(OR(AZ8<굴절률!$A$6,AZ8>굴절률!$A$44),"",IF(COUNTIFS(굴절률!$A$6:$A$44,AZ8)>0,INDEX(굴절률!$D$6:$D$44,MATCH(AZ8,굴절률!$A$6:$A$44,0)),INDEX(굴절률!$D$6:$D$44,MATCH(AZ8,굴절률!$A$6:$A$44,1))+(AZ8-INDEX(굴절률!$A$6:$A$44,MATCH(AZ8,굴절률!$A$6:$A$44,1)))*(INDEX(굴절률!$D$6:$D$44,MATCH(AZ8,굴절률!$A$6:$A$44,1)+1)-INDEX(굴절률!$D$6:$D$44,MATCH(AZ8,굴절률!$A$6:$A$44,1)))/(INDEX(굴절률!$A$6:$A$44,MATCH(AZ8,굴절률!$A$6:$A$44,1)+1)-INDEX(굴절률!$A$6:$A$44,MATCH(AZ8,굴절률!$A$6:$A$44,1)))))) -> 1.47054 | BB8: =설정!$C$16 -> 10 | BC8: =IF(OR(AZ8="",설정!$C$16="",설정!$C$16<8,설정!$C$16>15),"",IF(COUNTIFS('TMM 계산표'!$B$5:$I$5,설정!$C$16)>0,INDEX('TMM 계산표'!$B$6:$I$3806,MATCH(AZ8,'TMM 계산표'!$A$6:$A$3806,1),MATCH(설정!$C$16,'TMM 계산표'!$B$5:$I$5,0)),INDEX('TMM 계산표'!$B$6:$I$3806,MATCH(AZ8,'TMM 계산표'!$A$6:$A$3806,1),MATCH(설정!$C$16,'TMM 계산표'!$B$5:$I$5,1))+(설정!$C$16-INDEX('TMM 계산표'!$B$5:$I$5,1,MATCH(설정!$C$16,'TMM 계산표'!$B$5:$I$5,1)))*(INDEX('TMM 계산표'!$B$6:$I$3806,MATCH(AZ8,'TMM 계산표'!$A$6:$A$3806,1),MATCH(설정!$C$16,'TMM 계산표'!$B$5:$I$5,1)+1)-INDEX('TMM 계산표'!$B$6:$I$3806,MATCH(AZ8,'TMM 계산표'!$A$6:$A$3806,1),MATCH(설정!$C$16,'TMM 계산표'!$B$5:$I$5,1)))/(INDEX('TMM 계산표'!$B$5:$I$5,1,MATCH(설정!$C$16,'TMM 계산표'!$B$5:$I$5,1)+1)-INDEX('TMM 계산표'!$B$5:$I$5,1,MATCH(설정!$C$16,'TMM 계산표'!$B$5:$I$5,1))))) -> 97.244 | BD8: =IF(COUNT(H8:AT8)=0,"입력 필요",IF(COUNT(H8:AT8)<>39,"데이터 점검",IF(OR(설정!$C$16="",설정!$C$16<8,설정!$C$16>15),"Nb 두께 입력 확인",IF(OR(설정!$E$8>설정!$F$8,설정!$E$8<360,설정!$F$8>740),"검색 범위 오류",IF(AY8<>"","수동 파장",IF(OR(AZ8=설정!$E$8,AZ8=설정!$F$8),"경계 극값 확인","완료")))))) -> 완료 | BE8: =IF(AND(BE$5>=설정!$E$8,BE$5<=설정!$F$8),H8,"") | BF8: =IF(AND(BF$5>=설정!$E$8,BF$5<=설정!$F$8),I8,"") | BG8: =IF(AND(BG$5>=설정!$E$8,BG$5<=설정!$F$8),J8,"") | BH8: =IF(AND(BH$5>=설정!$E$8,BH$5<=설정!$F$8),K8,"") | BI8: =IF(AND(BI$5>=설정!$E$8,BI$5<=설정!$F$8),L8,"") | BJ8: =IF(AND(BJ$5>=설정!$E$8,BJ$5<=설정!$F$8),M8,"") | BK8: =IF(AND(BK$5>=설정!$E$8,BK$5<=설정!$F$8),N8,"") | BL8: =IF(AND(BL$5>=설정!$E$8,BL$5<=설정!$F$8),O8,"") -> 8.08 | ... CQ8: =IF(AND(CQ$5>=설정!$E$8,CQ$5<=설정!$F$8),AT8,"")
A9: 4 | B9: SiO2 균일도_04 | C9: 32.18 | D9: 5.51 | E9: 0.58 | F9: 7.17 | G9: SCI | H9: 19.83 | I9: 16.94 | J9: 14.72 | K9: 12.8 | L9: 11.2 | M9: 9.84 | N9: 8.72 | O9: 7.87 | P9: 7.23 | Q9: 6.79 | R9: 6.44 | S9: 6.22 | T9: 6.13 | U9: 6.14 | V9: 6.18 | W9: 6.26 | X9: 6.41 | Y9: 6.58 | Z9: 6.78 | AA9: 6.98 | AB9: 7.19 | AC9: 7.43 | AD9: 7.65 | AE9: 7.87 | AF9: 8.1 | AG9: 8.35 | AH9: 8.52 | AI9: 8.72 | AJ9: 8.96 | AK9: 9.12 | AL9: 9.34 | AM9: 9.48 | AN9: 9.67 | AO9: 9.84 | AP9: 10 | AQ9: 10.17 | AR9: 10.26 | AS9: 10.39 | AT9: 10.55 | AU9: =IF(OR(설정!$E$8>설정!$F$8,COUNT(H9:AT9)=0),"",MIN(BE9:CQ9)) -> 6.13 | AV9: =IF(AU9="","",SUMIFS($BE$5:$CQ$5,BE9:CQ9,AU9)/COUNTIFS(BE9:CQ9,AU9)) -> 480 | AW9: =IF(OR(설정!$E$8>설정!$F$8,COUNT(H9:AT9)=0),"",MAX(BE9:CQ9)) -> 7.87 | AX9: =IF(AW9="","",SUMIFS($BE$5:$CQ$5,BE9:CQ9,AW9)/COUNTIFS(BE9:CQ9,AW9)) -> 430 | AZ9: =IF(AY9<>"",AY9,IF(설정!$C$8="최소",AV9,AX9)) -> 480 | BA9: =IF(AZ9="","",IF(OR(AZ9<굴절률!$A$6,AZ9>굴절률!$A$44),"",IF(COUNTIFS(굴절률!$A$6:$A$44,AZ9)>0,INDEX(굴절률!$D$6:$D$44,MATCH(AZ9,굴절률!$A$6:$A$44,0)),INDEX(굴절률!$D$6:$D$44,MATCH(AZ9,굴절률!$A$6:$A$44,1))+(AZ9-INDEX(굴절률!$A$6:$A$44,MATCH(AZ9,굴절률!$A$6:$A$44,1)))*(INDEX(굴절률!$D$6:$D$44,MATCH(AZ9,굴절률!$A$6:$A$44,1)+1)-INDEX(굴절률!$D$6:$D$44,MATCH(AZ9,굴절률!$A$6:$A$44,1)))/(INDEX(굴절률!$A$6:$A$44,MATCH(AZ9,굴절률!$A$6:$A$44,1)+1)-INDEX(굴절률!$A$6:$A$44,MATCH(AZ9,굴절률!$A$6:$A$44,1)))))) -> 1.47069 | BB9: =설정!$C$16 -> 10 | BC9: =IF(OR(AZ9="",설정!$C$16="",설정!$C$16<8,설정!$C$16>15),"",IF(COUNTIFS('TMM 계산표'!$B$5:$I$5,설정!$C$16)>0,INDEX('TMM 계산표'!$B$6:$I$3806,MATCH(AZ9,'TMM 계산표'!$A$6:$A$3806,1),MATCH(설정!$C$16,'TMM 계산표'!$B$5:$I$5,0)),INDEX('TMM 계산표'!$B$6:$I$3806,MATCH(AZ9,'TMM 계산표'!$A$6:$A$3806,1),MATCH(설정!$C$16,'TMM 계산표'!$B$5:$I$5,1))+(설정!$C$16-INDEX('TMM 계산표'!$B$5:$I$5,1,MATCH(설정!$C$16,'TMM 계산표'!$B$5:$I$5,1)))*(INDEX('TMM 계산표'!$B$6:$I$3806,MATCH(AZ9,'TMM 계산표'!$A$6:$A$3806,1),MATCH(설정!$C$16,'TMM 계산표'!$B$5:$I$5,1)+1)-INDEX('TMM 계산표'!$B$6:$I$3806,MATCH(AZ9,'TMM 계산표'!$A$6:$A$3806,1),MATCH(설정!$C$16,'TMM 계산표'!$B$5:$I$5,1)))/(INDEX('TMM 계산표'!$B$5:$I$5,1,MATCH(설정!$C$16,'TMM 계산표'!$B$5:$I$5,1)+1)-INDEX('TMM 계산표'!$B$5:$I$5,1,MATCH(설정!$C$16,'TMM 계산표'!$B$5:$I$5,1))))) -> 96.286803 | BD9: =IF(COUNT(H9:AT9)=0,"입력 필요",IF(COUNT(H9:AT9)<>39,"데이터 점검",IF(OR(설정!$C$16="",설정!$C$16<8,설정!$C$16>15),"Nb 두께 입력 확인",IF(OR(설정!$E$8>설정!$F$8,설정!$E$8<360,설정!$F$8>740),"검색 범위 오류",IF(AY9<>"","수동 파장",IF(OR(AZ9=설정!$E$8,AZ9=설정!$F$8),"경계 극값 확인","완료")))))) -> 완료 | BE9: =IF(AND(BE$5>=설정!$E$8,BE$5<=설정!$F$8),H9,"") | BF9: =IF(AND(BF$5>=설정!$E$8,BF$5<=설정!$F$8),I9,"") | BG9: =IF(AND(BG$5>=설정!$E$8,BG$5<=설정!$F$8),J9,"") | BH9: =IF(AND(BH$5>=설정!$E$8,BH$5<=설정!$F$8),K9,"") | BI9: =IF(AND(BI$5>=설정!$E$8,BI$5<=설정!$F$8),L9,"") | BJ9: =IF(AND(BJ$5>=설정!$E$8,BJ$5<=설정!$F$8),M9,"") | BK9: =IF(AND(BK$5>=설정!$E$8,BK$5<=설정!$F$8),N9,"") | BL9: =IF(AND(BL$5>=설정!$E$8,BL$5<=설정!$F$8),O9,"") -> 7.87 | ... CQ9: =IF(AND(CQ$5>=설정!$E$8,CQ$5<=설정!$F$8),AT9,"")
A10: 5 | B10: SiO2 균일도_05 | C10: 32.32 | D10: 5.46 | E10: 0.73 | F10: 7.23 | G10: SCI | H10: 19.9 | I10: 17.02 | J10: 14.77 | K10: 12.83 | L10: 11.24 | M10: 9.86 | N10: 8.73 | O10: 7.88 | P10: 7.24 | Q10: 6.81 | R10: 6.44 | S10: 6.26 | T10: 6.16 | U10: 6.17 | V10: 6.23 | W10: 6.32 | X10: 6.46 | Y10: 6.64 | Z10: 6.85 | AA10: 7.05 | AB10: 7.26 | AC10: 7.49 | AD10: 7.72 | AE10: 7.93 | AF10: 8.18 | AG10: 8.41 | AH10: 8.59 | AI10: 8.8 | AJ10: 9.03 | AK10: 9.19 | AL10: 9.41 | AM10: 9.55 | AN10: 9.76 | AO10: 9.92 | AP10: 10.08 | AQ10: 10.23 | AR10: 10.31 | AS10: 10.48 | AT10: 10.63 | AU10: =IF(OR(설정!$E$8>설정!$F$8,COUNT(H10:AT10)=0),"",MIN(BE10:CQ10)) -> 6.16 | AV10: =IF(AU10="","",SUMIFS($BE$5:$CQ$5,BE10:CQ10,AU10)/COUNTIFS(BE10:CQ10,AU10)) -> 480 | AW10: =IF(OR(설정!$E$8>설정!$F$8,COUNT(H10:AT10)=0),"",MAX(BE10:CQ10)) -> 7.88 | AX10: =IF(AW10="","",SUMIFS($BE$5:$CQ$5,BE10:CQ10,AW10)/COUNTIFS(BE10:CQ10,AW10)) -> 430 | AZ10: =IF(AY10<>"",AY10,IF(설정!$C$8="최소",AV10,AX10)) -> 480 | BA10: =IF(AZ10="","",IF(OR(AZ10<굴절률!$A$6,AZ10>굴절률!$A$44),"",IF(COUNTIFS(굴절률!$A$6:$A$44,AZ10)>0,INDEX(굴절률!$D$6:$D$44,MATCH(AZ10,굴절률!$A$6:$A$44,0)),INDEX(굴절률!$D$6:$D$44,MATCH(AZ10,굴절률!$A$6:$A$44,1))+(AZ10-INDEX(굴절률!$A$6:$A$44,MATCH(AZ10,굴절률!$A$6:$A$44,1)))*(INDEX(굴절률!$D$6:$D$44,MATCH(AZ10,굴절률!$A$6:$A$44,1)+1)-INDEX(굴절률!$D$6:$D$44,MATCH(AZ10,굴절률!$A$6:$A$44,1)))/(INDEX(굴절률!$A$6:$A$44,MATCH(AZ10,굴절률!$A$6:$A$44,1)+1)-INDEX(굴절률!$A$6:$A$44,MATCH(AZ10,굴절률!$A$6:$A$44,1)))))) -> 1.47069 | BB10: =설정!$C$16 -> 10 | BC10: =IF(OR(AZ10="",설정!$C$16="",설정!$C$16<8,설정!$C$16>15),"",IF(COUNTIFS('TMM 계산표'!$B$5:$I$5,설정!$C$16)>0,INDEX('TMM 계산표'!$B$6:$I$3806,MATCH(AZ10,'TMM 계산표'!$A$6:$A$3806,1),MATCH(설정!$C$16,'TMM 계산표'!$B$5:$I$5,0)),INDEX('TMM 계산표'!$B$6:$I$3806,MATCH(AZ10,'TMM 계산표'!$A$6:$A$3806,1),MATCH(설정!$C$16,'TMM 계산표'!$B$5:$I$5,1))+(설정!$C$16-INDEX('TMM 계산표'!$B$5:$I$5,1,MATCH(설정!$C$16,'TMM 계산표'!$B$5:$I$5,1)))*(INDEX('TMM 계산표'!$B$6:$I$3806,MATCH(AZ10,'TMM 계산표'!$A$6:$A$3806,1),MATCH(설정!$C$16,'TMM 계산표'!$B$5:$I$5,1)+1)-INDEX('TMM 계산표'!$B$6:$I$3806,MATCH(AZ10,'TMM 계산표'!$A$6:$A$3806,1),MATCH(설정!$C$16,'TMM 계산표'!$B$5:$I$5,1)))/(INDEX('TMM 계산표'!$B$5:$I$5,1,MATCH(설정!$C$16,'TMM 계산표'!$B$5:$I$5,1)+1)-INDEX('TMM 계산표'!$B$5:$I$5,1,MATCH(설정!$C$16,'TMM 계산표'!$B$5:$I$5,1))))) -> 96.286803 | BD10: =IF(COUNT(H10:AT10)=0,"입력 필요",IF(COUNT(H10:AT10)<>39,"데이터 점검",IF(OR(설정!$C$16="",설정!$C$16<8,설정!$C$16>15),"Nb 두께 입력 확인",IF(OR(설정!$E$8>설정!$F$8,설정!$E$8<360,설정!$F$8>740),"검색 범위 오류",IF(AY10<>"","수동 파장",IF(OR(AZ10=설정!$E$8,AZ10=설정!$F$8),"경계 극값 확인","완료")))))) -> 완료 | BE10: =IF(AND(BE$5>=설정!$E$8,BE$5<=설정!$F$8),H10,"") | BF10: =IF(AND(BF$5>=설정!$E$8,BF$5<=설정!$F$8),I10,"") | BG10: =IF(AND(BG$5>=설정!$E$8,BG$5<=설정!$F$8),J10,"") | BH10: =IF(AND(BH$5>=설정!$E$8,BH$5<=설정!$F$8),K10,"") | BI10: =IF(AND(BI$5>=설정!$E$8,BI$5<=설정!$F$8),L10,"") | BJ10: =IF(AND(BJ$5>=설정!$E$8,BJ$5<=설정!$F$8),M10,"") | BK10: =IF(AND(BK$5>=설정!$E$8,BK$5<=설정!$F$8),N10,"") | BL10: =IF(AND(BL$5>=설정!$E$8,BL$5<=설정!$F$8),O10,"") -> 7.88 | ... CQ10: =IF(AND(CQ$5>=설정!$E$8,CQ$5<=설정!$F$8),AT10,"")
A11: 6 | B11: SiO2 균일도_06 | C11: 32.33 | D11: 5.34 | E11: 0.69 | F11: 7.23 | G11: SCI | H11: 19.55 | I11: 16.73 | J11: 14.57 | K11: 12.68 | L11: 11.12 | M11: 9.79 | N11: 8.68 | O11: 7.88 | P11: 7.27 | Q11: 6.82 | R11: 6.48 | S11: 6.3 | T11: 6.2 | U11: 6.22 | V11: 6.26 | W11: 6.35 | X11: 6.49 | Y11: 6.66 | Z11: 6.86 | AA11: 7.05 | AB11: 7.27 | AC11: 7.5 | AD11: 7.72 | AE11: 7.92 | AF11: 8.17 | AG11: 8.39 | AH11: 8.56 | AI11: 8.78 | AJ11: 8.99 | AK11: 9.16 | AL11: 9.37 | AM11: 9.51 | AN11: 9.69 | AO11: 9.86 | AP11: 10.02 | AQ11: 10.17 | AR11: 10.25 | AS11: 10.4 | AT11: 10.52 | AU11: =IF(OR(설정!$E$8>설정!$F$8,COUNT(H11:AT11)=0),"",MIN(BE11:CQ11)) -> 6.2 | AV11: =IF(AU11="","",SUMIFS($BE$5:$CQ$5,BE11:CQ11,AU11)/COUNTIFS(BE11:CQ11,AU11)) -> 480 | AW11: =IF(OR(설정!$E$8>설정!$F$8,COUNT(H11:AT11)=0),"",MAX(BE11:CQ11)) -> 7.88 | AX11: =IF(AW11="","",SUMIFS($BE$5:$CQ$5,BE11:CQ11,AW11)/COUNTIFS(BE11:CQ11,AW11)) -> 430 | AZ11: =IF(AY11<>"",AY11,IF(설정!$C$8="최소",AV11,AX11)) -> 480 | BA11: =IF(AZ11="","",IF(OR(AZ11<굴절률!$A$6,AZ11>굴절률!$A$44),"",IF(COUNTIFS(굴절률!$A$6:$A$44,AZ11)>0,INDEX(굴절률!$D$6:$D$44,MATCH(AZ11,굴절률!$A$6:$A$44,0)),INDEX(굴절률!$D$6:$D$44,MATCH(AZ11,굴절률!$A$6:$A$44,1))+(AZ11-INDEX(굴절률!$A$6:$A$44,MATCH(AZ11,굴절률!$A$6:$A$44,1)))*(INDEX(굴절률!$D$6:$D$44,MATCH(AZ11,굴절률!$A$6:$A$44,1)+1)-INDEX(굴절률!$D$6:$D$44,MATCH(AZ11,굴절률!$A$6:$A$44,1)))/(INDEX(굴절률!$A$6:$A$44,MATCH(AZ11,굴절률!$A$6:$A$44,1)+1)-INDEX(굴절률!$A$6:$A$44,MATCH(AZ11,굴절률!$A$6:$A$44,1)))))) -> 1.47069 | BB11: =설정!$C$16 -> 10 | BC11: =IF(OR(AZ11="",설정!$C$16="",설정!$C$16<8,설정!$C$16>15),"",IF(COUNTIFS('TMM 계산표'!$B$5:$I$5,설정!$C$16)>0,INDEX('TMM 계산표'!$B$6:$I$3806,MATCH(AZ11,'TMM 계산표'!$A$6:$A$3806,1),MATCH(설정!$C$16,'TMM 계산표'!$B$5:$I$5,0)),INDEX('TMM 계산표'!$B$6:$I$3806,MATCH(AZ11,'TMM 계산표'!$A$6:$A$3806,1),MATCH(설정!$C$16,'TMM 계산표'!$B$5:$I$5,1))+(설정!$C$16-INDEX('TMM 계산표'!$B$5:$I$5,1,MATCH(설정!$C$16,'TMM 계산표'!$B$5:$I$5,1)))*(INDEX('TMM 계산표'!$B$6:$I$3806,MATCH(AZ11,'TMM 계산표'!$A$6:$A$3806,1),MATCH(설정!$C$16,'TMM 계산표'!$B$5:$I$5,1)+1)-INDEX('TMM 계산표'!$B$6:$I$3806,MATCH(AZ11,'TMM 계산표'!$A$6:$A$3806,1),MATCH(설정!$C$16,'TMM 계산표'!$B$5:$I$5,1)))/(INDEX('TMM 계산표'!$B$5:$I$5,1,MATCH(설정!$C$16,'TMM 계산표'!$B$5:$I$5,1)+1)-INDEX('TMM 계산표'!$B$5:$I$5,1,MATCH(설정!$C$16,'TMM 계산표'!$B$5:$I$5,1))))) -> 96.286803 | BD11: =IF(COUNT(H11:AT11)=0,"입력 필요",IF(COUNT(H11:AT11)<>39,"데이터 점검",IF(OR(설정!$C$16="",설정!$C$16<8,설정!$C$16>15),"Nb 두께 입력 확인",IF(OR(설정!$E$8>설정!$F$8,설정!$E$8<360,설정!$F$8>740),"검색 범위 오류",IF(AY11<>"","수동 파장",IF(OR(AZ11=설정!$E$8,AZ11=설정!$F$8),"경계 극값 확인","완료")))))) -> 완료 | BE11: =IF(AND(BE$5>=설정!$E$8,BE$5<=설정!$F$8),H11,"") | BF11: =IF(AND(BF$5>=설정!$E$8,BF$5<=설정!$F$8),I11,"") | BG11: =IF(AND(BG$5>=설정!$E$8,BG$5<=설정!$F$8),J11,"") | BH11: =IF(AND(BH$5>=설정!$E$8,BH$5<=설정!$F$8),K11,"") | BI11: =IF(AND(BI$5>=설정!$E$8,BI$5<=설정!$F$8),L11,"") | BJ11: =IF(AND(BJ$5>=설정!$E$8,BJ$5<=설정!$F$8),M11,"") | BK11: =IF(AND(BK$5>=설정!$E$8,BK$5<=설정!$F$8),N11,"") | BL11: =IF(AND(BL$5>=설정!$E$8,BL$5<=설정!$F$8),O11,"") -> 7.88 | ... CQ11: =IF(AND(CQ$5>=설정!$E$8,CQ$5<=설정!$F$8),AT11,"")
